
2020-10-28 13:12:32,599 INFO: errors [in C:\Users\Amna\class-demos\fyyur\starter_code\app.py:395]
2020-10-28 13:13:01,809 INFO: errors [in C:\Users\Amna\class-demos\fyyur\starter_code\app.py:395]
2020-10-28 13:13:16,081 INFO: errors [in C:\Users\Amna\class-demos\fyyur\starter_code\app.py:395]
2020-10-28 13:13:16,112 INFO: errors [in app.py:395]
2020-10-28 13:13:16,112 INFO: errors [in app.py:395]
2020-10-28 13:13:31,139 ERROR: Exception on /artists/2 [GET] [in C:\Users\Amna\AppData\Local\Programs\Python\Python38\lib\site-packages\flask\app.py:1891]
Traceback (most recent call last):
  File "C:\Users\Amna\AppData\Local\Programs\Python\Python38\lib\site-packages\sqlalchemy\util\_collections.py", line 1020, in __call__
    return self.registry[key]
KeyError: 9160

During handling of the above exception, another exception occurred:

Traceback (most recent call last):
  File "C:\Users\Amna\AppData\Local\Programs\Python\Python38\lib\site-packages\flask\app.py", line 2447, in wsgi_app
    response = self.full_dispatch_request()
  File "C:\Users\Amna\AppData\Local\Programs\Python\Python38\lib\site-packages\flask\app.py", line 1952, in full_dispatch_request
    rv = self.handle_user_exception(e)
  File "C:\Users\Amna\AppData\Local\Programs\Python\Python38\lib\site-packages\flask\app.py", line 1821, in handle_user_exception
    reraise(exc_type, exc_value, tb)
  File "C:\Users\Amna\AppData\Local\Programs\Python\Python38\lib\site-packages\flask\_compat.py", line 39, in reraise
    raise value
  File "C:\Users\Amna\AppData\Local\Programs\Python\Python38\lib\site-packages\flask\app.py", line 1950, in full_dispatch_request
    rv = self.dispatch_request()
  File "C:\Users\Amna\AppData\Local\Programs\Python\Python38\lib\site-packages\flask\app.py", line 1936, in dispatch_request
    return self.view_functions[rule.endpoint](**req.view_args)
  File "app.py", line 212, in show_artist
    artist=Artist.query.get(artist_id)
  File "C:\Users\Amna\AppData\Local\Programs\Python\Python38\lib\site-packages\flask_sqlalchemy\__init__.py", line 514, in __get__
    return type.query_class(mapper, session=self.sa.session())
  File "C:\Users\Amna\AppData\Local\Programs\Python\Python38\lib\site-packages\sqlalchemy\orm\scoping.py", line 78, in __call__
    return self.registry()
  File "C:\Users\Amna\AppData\Local\Programs\Python\Python38\lib\site-packages\sqlalchemy\util\_collections.py", line 1022, in __call__
    return self.registry.setdefault(key, self.createfunc())
  File "C:\Users\Amna\AppData\Local\Programs\Python\Python38\lib\site-packages\sqlalchemy\orm\session.py", line 3300, in __call__
    return self.class_(**local_kw)
  File "C:\Users\Amna\AppData\Local\Programs\Python\Python38\lib\site-packages\flask_sqlalchemy\__init__.py", line 137, in __init__
    track_modifications = app.config['SQLALCHEMY_TRACK_MODIFICATIONS']
KeyError: 'SQLALCHEMY_TRACK_MODIFICATIONS'
2020-10-28 13:13:31,139 ERROR: Exception on /artists/2 [GET] [in C:\Users\Amna\AppData\Local\Programs\Python\Python38\lib\site-packages\flask\app.py:1891]
Traceback (most recent call last):
  File "C:\Users\Amna\AppData\Local\Programs\Python\Python38\lib\site-packages\sqlalchemy\util\_collections.py", line 1020, in __call__
    return self.registry[key]
KeyError: 9160

During handling of the above exception, another exception occurred:

Traceback (most recent call last):
  File "C:\Users\Amna\AppData\Local\Programs\Python\Python38\lib\site-packages\flask\app.py", line 2447, in wsgi_app
    response = self.full_dispatch_request()
  File "C:\Users\Amna\AppData\Local\Programs\Python\Python38\lib\site-packages\flask\app.py", line 1952, in full_dispatch_request
    rv = self.handle_user_exception(e)
  File "C:\Users\Amna\AppData\Local\Programs\Python\Python38\lib\site-packages\flask\app.py", line 1821, in handle_user_exception
    reraise(exc_type, exc_value, tb)
  File "C:\Users\Amna\AppData\Local\Programs\Python\Python38\lib\site-packages\flask\_compat.py", line 39, in reraise
    raise value
  File "C:\Users\Amna\AppData\Local\Programs\Python\Python38\lib\site-packages\flask\app.py", line 1950, in full_dispatch_request
    rv = self.dispatch_request()
  File "C:\Users\Amna\AppData\Local\Programs\Python\Python38\lib\site-packages\flask\app.py", line 1936, in dispatch_request
    return self.view_functions[rule.endpoint](**req.view_args)
  File "app.py", line 212, in show_artist
    artist=Artist.query.get(artist_id)
  File "C:\Users\Amna\AppData\Local\Programs\Python\Python38\lib\site-packages\flask_sqlalchemy\__init__.py", line 514, in __get__
    return type.query_class(mapper, session=self.sa.session())
  File "C:\Users\Amna\AppData\Local\Programs\Python\Python38\lib\site-packages\sqlalchemy\orm\scoping.py", line 78, in __call__
    return self.registry()
  File "C:\Users\Amna\AppData\Local\Programs\Python\Python38\lib\site-packages\sqlalchemy\util\_collections.py", line 1022, in __call__
    return self.registry.setdefault(key, self.createfunc())
  File "C:\Users\Amna\AppData\Local\Programs\Python\Python38\lib\site-packages\sqlalchemy\orm\session.py", line 3300, in __call__
    return self.class_(**local_kw)
  File "C:\Users\Amna\AppData\Local\Programs\Python\Python38\lib\site-packages\flask_sqlalchemy\__init__.py", line 137, in __init__
    track_modifications = app.config['SQLALCHEMY_TRACK_MODIFICATIONS']
KeyError: 'SQLALCHEMY_TRACK_MODIFICATIONS'
2020-10-28 13:13:34,461 ERROR: Exception on /artists [GET] [in C:\Users\Amna\AppData\Local\Programs\Python\Python38\lib\site-packages\flask\app.py:1891]
Traceback (most recent call last):
  File "C:\Users\Amna\AppData\Local\Programs\Python\Python38\lib\site-packages\sqlalchemy\util\_collections.py", line 1020, in __call__
    return self.registry[key]
KeyError: 9900

During handling of the above exception, another exception occurred:

Traceback (most recent call last):
  File "C:\Users\Amna\AppData\Local\Programs\Python\Python38\lib\site-packages\flask\app.py", line 2447, in wsgi_app
    response = self.full_dispatch_request()
  File "C:\Users\Amna\AppData\Local\Programs\Python\Python38\lib\site-packages\flask\app.py", line 1952, in full_dispatch_request
    rv = self.handle_user_exception(e)
  File "C:\Users\Amna\AppData\Local\Programs\Python\Python38\lib\site-packages\flask\app.py", line 1821, in handle_user_exception
    reraise(exc_type, exc_value, tb)
  File "C:\Users\Amna\AppData\Local\Programs\Python\Python38\lib\site-packages\flask\_compat.py", line 39, in reraise
    raise value
  File "C:\Users\Amna\AppData\Local\Programs\Python\Python38\lib\site-packages\flask\app.py", line 1950, in full_dispatch_request
    rv = self.dispatch_request()
  File "C:\Users\Amna\AppData\Local\Programs\Python\Python38\lib\site-packages\flask\app.py", line 1936, in dispatch_request
    return self.view_functions[rule.endpoint](**req.view_args)
  File "app.py", line 187, in artists
    return render_template('pages/artists.html', artists=Artist.query.all())
  File "C:\Users\Amna\AppData\Local\Programs\Python\Python38\lib\site-packages\flask_sqlalchemy\__init__.py", line 514, in __get__
    return type.query_class(mapper, session=self.sa.session())
  File "C:\Users\Amna\AppData\Local\Programs\Python\Python38\lib\site-packages\sqlalchemy\orm\scoping.py", line 78, in __call__
    return self.registry()
  File "C:\Users\Amna\AppData\Local\Programs\Python\Python38\lib\site-packages\sqlalchemy\util\_collections.py", line 1022, in __call__
    return self.registry.setdefault(key, self.createfunc())
  File "C:\Users\Amna\AppData\Local\Programs\Python\Python38\lib\site-packages\sqlalchemy\orm\session.py", line 3300, in __call__
    return self.class_(**local_kw)
  File "C:\Users\Amna\AppData\Local\Programs\Python\Python38\lib\site-packages\flask_sqlalchemy\__init__.py", line 137, in __init__
    track_modifications = app.config['SQLALCHEMY_TRACK_MODIFICATIONS']
KeyError: 'SQLALCHEMY_TRACK_MODIFICATIONS'
2020-10-28 13:13:34,461 ERROR: Exception on /artists [GET] [in C:\Users\Amna\AppData\Local\Programs\Python\Python38\lib\site-packages\flask\app.py:1891]
Traceback (most recent call last):
  File "C:\Users\Amna\AppData\Local\Programs\Python\Python38\lib\site-packages\sqlalchemy\util\_collections.py", line 1020, in __call__
    return self.registry[key]
KeyError: 9900

During handling of the above exception, another exception occurred:

Traceback (most recent call last):
  File "C:\Users\Amna\AppData\Local\Programs\Python\Python38\lib\site-packages\flask\app.py", line 2447, in wsgi_app
    response = self.full_dispatch_request()
  File "C:\Users\Amna\AppData\Local\Programs\Python\Python38\lib\site-packages\flask\app.py", line 1952, in full_dispatch_request
    rv = self.handle_user_exception(e)
  File "C:\Users\Amna\AppData\Local\Programs\Python\Python38\lib\site-packages\flask\app.py", line 1821, in handle_user_exception
    reraise(exc_type, exc_value, tb)
  File "C:\Users\Amna\AppData\Local\Programs\Python\Python38\lib\site-packages\flask\_compat.py", line 39, in reraise
    raise value
  File "C:\Users\Amna\AppData\Local\Programs\Python\Python38\lib\site-packages\flask\app.py", line 1950, in full_dispatch_request
    rv = self.dispatch_request()
  File "C:\Users\Amna\AppData\Local\Programs\Python\Python38\lib\site-packages\flask\app.py", line 1936, in dispatch_request
    return self.view_functions[rule.endpoint](**req.view_args)
  File "app.py", line 187, in artists
    return render_template('pages/artists.html', artists=Artist.query.all())
  File "C:\Users\Amna\AppData\Local\Programs\Python\Python38\lib\site-packages\flask_sqlalchemy\__init__.py", line 514, in __get__
    return type.query_class(mapper, session=self.sa.session())
  File "C:\Users\Amna\AppData\Local\Programs\Python\Python38\lib\site-packages\sqlalchemy\orm\scoping.py", line 78, in __call__
    return self.registry()
  File "C:\Users\Amna\AppData\Local\Programs\Python\Python38\lib\site-packages\sqlalchemy\util\_collections.py", line 1022, in __call__
    return self.registry.setdefault(key, self.createfunc())
  File "C:\Users\Amna\AppData\Local\Programs\Python\Python38\lib\site-packages\sqlalchemy\orm\session.py", line 3300, in __call__
    return self.class_(**local_kw)
  File "C:\Users\Amna\AppData\Local\Programs\Python\Python38\lib\site-packages\flask_sqlalchemy\__init__.py", line 137, in __init__
    track_modifications = app.config['SQLALCHEMY_TRACK_MODIFICATIONS']
KeyError: 'SQLALCHEMY_TRACK_MODIFICATIONS'
2020-10-28 13:13:36,236 ERROR: Exception on /venues [GET] [in C:\Users\Amna\AppData\Local\Programs\Python\Python38\lib\site-packages\flask\app.py:1891]
Traceback (most recent call last):
  File "C:\Users\Amna\AppData\Local\Programs\Python\Python38\lib\site-packages\sqlalchemy\util\_collections.py", line 1020, in __call__
    return self.registry[key]
KeyError: 11608

During handling of the above exception, another exception occurred:

Traceback (most recent call last):
  File "C:\Users\Amna\AppData\Local\Programs\Python\Python38\lib\site-packages\flask\app.py", line 2447, in wsgi_app
    response = self.full_dispatch_request()
  File "C:\Users\Amna\AppData\Local\Programs\Python\Python38\lib\site-packages\flask\app.py", line 1952, in full_dispatch_request
    rv = self.handle_user_exception(e)
  File "C:\Users\Amna\AppData\Local\Programs\Python\Python38\lib\site-packages\flask\app.py", line 1821, in handle_user_exception
    reraise(exc_type, exc_value, tb)
  File "C:\Users\Amna\AppData\Local\Programs\Python\Python38\lib\site-packages\flask\_compat.py", line 39, in reraise
    raise value
  File "C:\Users\Amna\AppData\Local\Programs\Python\Python38\lib\site-packages\flask\app.py", line 1950, in full_dispatch_request
    rv = self.dispatch_request()
  File "C:\Users\Amna\AppData\Local\Programs\Python\Python38\lib\site-packages\flask\app.py", line 1936, in dispatch_request
    return self.view_functions[rule.endpoint](**req.view_args)
  File "app.py", line 69, in venues
    venuesdata=Venue.query.all()
  File "C:\Users\Amna\AppData\Local\Programs\Python\Python38\lib\site-packages\flask_sqlalchemy\__init__.py", line 514, in __get__
    return type.query_class(mapper, session=self.sa.session())
  File "C:\Users\Amna\AppData\Local\Programs\Python\Python38\lib\site-packages\sqlalchemy\orm\scoping.py", line 78, in __call__
    return self.registry()
  File "C:\Users\Amna\AppData\Local\Programs\Python\Python38\lib\site-packages\sqlalchemy\util\_collections.py", line 1022, in __call__
    return self.registry.setdefault(key, self.createfunc())
  File "C:\Users\Amna\AppData\Local\Programs\Python\Python38\lib\site-packages\sqlalchemy\orm\session.py", line 3300, in __call__
    return self.class_(**local_kw)
  File "C:\Users\Amna\AppData\Local\Programs\Python\Python38\lib\site-packages\flask_sqlalchemy\__init__.py", line 137, in __init__
    track_modifications = app.config['SQLALCHEMY_TRACK_MODIFICATIONS']
KeyError: 'SQLALCHEMY_TRACK_MODIFICATIONS'
2020-10-28 13:13:36,236 ERROR: Exception on /venues [GET] [in C:\Users\Amna\AppData\Local\Programs\Python\Python38\lib\site-packages\flask\app.py:1891]
Traceback (most recent call last):
  File "C:\Users\Amna\AppData\Local\Programs\Python\Python38\lib\site-packages\sqlalchemy\util\_collections.py", line 1020, in __call__
    return self.registry[key]
KeyError: 11608

During handling of the above exception, another exception occurred:

Traceback (most recent call last):
  File "C:\Users\Amna\AppData\Local\Programs\Python\Python38\lib\site-packages\flask\app.py", line 2447, in wsgi_app
    response = self.full_dispatch_request()
  File "C:\Users\Amna\AppData\Local\Programs\Python\Python38\lib\site-packages\flask\app.py", line 1952, in full_dispatch_request
    rv = self.handle_user_exception(e)
  File "C:\Users\Amna\AppData\Local\Programs\Python\Python38\lib\site-packages\flask\app.py", line 1821, in handle_user_exception
    reraise(exc_type, exc_value, tb)
  File "C:\Users\Amna\AppData\Local\Programs\Python\Python38\lib\site-packages\flask\_compat.py", line 39, in reraise
    raise value
  File "C:\Users\Amna\AppData\Local\Programs\Python\Python38\lib\site-packages\flask\app.py", line 1950, in full_dispatch_request
    rv = self.dispatch_request()
  File "C:\Users\Amna\AppData\Local\Programs\Python\Python38\lib\site-packages\flask\app.py", line 1936, in dispatch_request
    return self.view_functions[rule.endpoint](**req.view_args)
  File "app.py", line 69, in venues
    venuesdata=Venue.query.all()
  File "C:\Users\Amna\AppData\Local\Programs\Python\Python38\lib\site-packages\flask_sqlalchemy\__init__.py", line 514, in __get__
    return type.query_class(mapper, session=self.sa.session())
  File "C:\Users\Amna\AppData\Local\Programs\Python\Python38\lib\site-packages\sqlalchemy\orm\scoping.py", line 78, in __call__
    return self.registry()
  File "C:\Users\Amna\AppData\Local\Programs\Python\Python38\lib\site-packages\sqlalchemy\util\_collections.py", line 1022, in __call__
    return self.registry.setdefault(key, self.createfunc())
  File "C:\Users\Amna\AppData\Local\Programs\Python\Python38\lib\site-packages\sqlalchemy\orm\session.py", line 3300, in __call__
    return self.class_(**local_kw)
  File "C:\Users\Amna\AppData\Local\Programs\Python\Python38\lib\site-packages\flask_sqlalchemy\__init__.py", line 137, in __init__
    track_modifications = app.config['SQLALCHEMY_TRACK_MODIFICATIONS']
KeyError: 'SQLALCHEMY_TRACK_MODIFICATIONS'
2020-10-28 13:13:37,299 ERROR: Exception on /artists [GET] [in C:\Users\Amna\AppData\Local\Programs\Python\Python38\lib\site-packages\flask\app.py:1891]
Traceback (most recent call last):
  File "C:\Users\Amna\AppData\Local\Programs\Python\Python38\lib\site-packages\sqlalchemy\util\_collections.py", line 1020, in __call__
    return self.registry[key]
KeyError: 336

During handling of the above exception, another exception occurred:

Traceback (most recent call last):
  File "C:\Users\Amna\AppData\Local\Programs\Python\Python38\lib\site-packages\flask\app.py", line 2447, in wsgi_app
    response = self.full_dispatch_request()
  File "C:\Users\Amna\AppData\Local\Programs\Python\Python38\lib\site-packages\flask\app.py", line 1952, in full_dispatch_request
    rv = self.handle_user_exception(e)
  File "C:\Users\Amna\AppData\Local\Programs\Python\Python38\lib\site-packages\flask\app.py", line 1821, in handle_user_exception
    reraise(exc_type, exc_value, tb)
  File "C:\Users\Amna\AppData\Local\Programs\Python\Python38\lib\site-packages\flask\_compat.py", line 39, in reraise
    raise value
  File "C:\Users\Amna\AppData\Local\Programs\Python\Python38\lib\site-packages\flask\app.py", line 1950, in full_dispatch_request
    rv = self.dispatch_request()
  File "C:\Users\Amna\AppData\Local\Programs\Python\Python38\lib\site-packages\flask\app.py", line 1936, in dispatch_request
    return self.view_functions[rule.endpoint](**req.view_args)
  File "app.py", line 187, in artists
    return render_template('pages/artists.html', artists=Artist.query.all())
  File "C:\Users\Amna\AppData\Local\Programs\Python\Python38\lib\site-packages\flask_sqlalchemy\__init__.py", line 514, in __get__
    return type.query_class(mapper, session=self.sa.session())
  File "C:\Users\Amna\AppData\Local\Programs\Python\Python38\lib\site-packages\sqlalchemy\orm\scoping.py", line 78, in __call__
    return self.registry()
  File "C:\Users\Amna\AppData\Local\Programs\Python\Python38\lib\site-packages\sqlalchemy\util\_collections.py", line 1022, in __call__
    return self.registry.setdefault(key, self.createfunc())
  File "C:\Users\Amna\AppData\Local\Programs\Python\Python38\lib\site-packages\sqlalchemy\orm\session.py", line 3300, in __call__
    return self.class_(**local_kw)
  File "C:\Users\Amna\AppData\Local\Programs\Python\Python38\lib\site-packages\flask_sqlalchemy\__init__.py", line 137, in __init__
    track_modifications = app.config['SQLALCHEMY_TRACK_MODIFICATIONS']
KeyError: 'SQLALCHEMY_TRACK_MODIFICATIONS'
2020-10-28 13:13:37,299 ERROR: Exception on /artists [GET] [in C:\Users\Amna\AppData\Local\Programs\Python\Python38\lib\site-packages\flask\app.py:1891]
Traceback (most recent call last):
  File "C:\Users\Amna\AppData\Local\Programs\Python\Python38\lib\site-packages\sqlalchemy\util\_collections.py", line 1020, in __call__
    return self.registry[key]
KeyError: 336

During handling of the above exception, another exception occurred:

Traceback (most recent call last):
  File "C:\Users\Amna\AppData\Local\Programs\Python\Python38\lib\site-packages\flask\app.py", line 2447, in wsgi_app
    response = self.full_dispatch_request()
  File "C:\Users\Amna\AppData\Local\Programs\Python\Python38\lib\site-packages\flask\app.py", line 1952, in full_dispatch_request
    rv = self.handle_user_exception(e)
  File "C:\Users\Amna\AppData\Local\Programs\Python\Python38\lib\site-packages\flask\app.py", line 1821, in handle_user_exception
    reraise(exc_type, exc_value, tb)
  File "C:\Users\Amna\AppData\Local\Programs\Python\Python38\lib\site-packages\flask\_compat.py", line 39, in reraise
    raise value
  File "C:\Users\Amna\AppData\Local\Programs\Python\Python38\lib\site-packages\flask\app.py", line 1950, in full_dispatch_request
    rv = self.dispatch_request()
  File "C:\Users\Amna\AppData\Local\Programs\Python\Python38\lib\site-packages\flask\app.py", line 1936, in dispatch_request
    return self.view_functions[rule.endpoint](**req.view_args)
  File "app.py", line 187, in artists
    return render_template('pages/artists.html', artists=Artist.query.all())
  File "C:\Users\Amna\AppData\Local\Programs\Python\Python38\lib\site-packages\flask_sqlalchemy\__init__.py", line 514, in __get__
    return type.query_class(mapper, session=self.sa.session())
  File "C:\Users\Amna\AppData\Local\Programs\Python\Python38\lib\site-packages\sqlalchemy\orm\scoping.py", line 78, in __call__
    return self.registry()
  File "C:\Users\Amna\AppData\Local\Programs\Python\Python38\lib\site-packages\sqlalchemy\util\_collections.py", line 1022, in __call__
    return self.registry.setdefault(key, self.createfunc())
  File "C:\Users\Amna\AppData\Local\Programs\Python\Python38\lib\site-packages\sqlalchemy\orm\session.py", line 3300, in __call__
    return self.class_(**local_kw)
  File "C:\Users\Amna\AppData\Local\Programs\Python\Python38\lib\site-packages\flask_sqlalchemy\__init__.py", line 137, in __init__
    track_modifications = app.config['SQLALCHEMY_TRACK_MODIFICATIONS']
KeyError: 'SQLALCHEMY_TRACK_MODIFICATIONS'
2020-10-28 13:13:37,926 ERROR: Exception on /shows [GET] [in C:\Users\Amna\AppData\Local\Programs\Python\Python38\lib\site-packages\flask\app.py:1891]
Traceback (most recent call last):
  File "C:\Users\Amna\AppData\Local\Programs\Python\Python38\lib\site-packages\sqlalchemy\util\_collections.py", line 1020, in __call__
    return self.registry[key]
KeyError: 6980

During handling of the above exception, another exception occurred:

Traceback (most recent call last):
  File "C:\Users\Amna\AppData\Local\Programs\Python\Python38\lib\site-packages\flask\app.py", line 2447, in wsgi_app
    response = self.full_dispatch_request()
  File "C:\Users\Amna\AppData\Local\Programs\Python\Python38\lib\site-packages\flask\app.py", line 1952, in full_dispatch_request
    rv = self.handle_user_exception(e)
  File "C:\Users\Amna\AppData\Local\Programs\Python\Python38\lib\site-packages\flask\app.py", line 1821, in handle_user_exception
    reraise(exc_type, exc_value, tb)
  File "C:\Users\Amna\AppData\Local\Programs\Python\Python38\lib\site-packages\flask\_compat.py", line 39, in reraise
    raise value
  File "C:\Users\Amna\AppData\Local\Programs\Python\Python38\lib\site-packages\flask\app.py", line 1950, in full_dispatch_request
    rv = self.dispatch_request()
  File "C:\Users\Amna\AppData\Local\Programs\Python\Python38\lib\site-packages\flask\app.py", line 1936, in dispatch_request
    return self.view_functions[rule.endpoint](**req.view_args)
  File "app.py", line 348, in shows
    return render_template('pages/shows.html', shows=Show.query.all())
  File "C:\Users\Amna\AppData\Local\Programs\Python\Python38\lib\site-packages\flask_sqlalchemy\__init__.py", line 514, in __get__
    return type.query_class(mapper, session=self.sa.session())
  File "C:\Users\Amna\AppData\Local\Programs\Python\Python38\lib\site-packages\sqlalchemy\orm\scoping.py", line 78, in __call__
    return self.registry()
  File "C:\Users\Amna\AppData\Local\Programs\Python\Python38\lib\site-packages\sqlalchemy\util\_collections.py", line 1022, in __call__
    return self.registry.setdefault(key, self.createfunc())
  File "C:\Users\Amna\AppData\Local\Programs\Python\Python38\lib\site-packages\sqlalchemy\orm\session.py", line 3300, in __call__
    return self.class_(**local_kw)
  File "C:\Users\Amna\AppData\Local\Programs\Python\Python38\lib\site-packages\flask_sqlalchemy\__init__.py", line 137, in __init__
    track_modifications = app.config['SQLALCHEMY_TRACK_MODIFICATIONS']
KeyError: 'SQLALCHEMY_TRACK_MODIFICATIONS'
2020-10-28 13:13:37,926 ERROR: Exception on /shows [GET] [in C:\Users\Amna\AppData\Local\Programs\Python\Python38\lib\site-packages\flask\app.py:1891]
Traceback (most recent call last):
  File "C:\Users\Amna\AppData\Local\Programs\Python\Python38\lib\site-packages\sqlalchemy\util\_collections.py", line 1020, in __call__
    return self.registry[key]
KeyError: 6980

During handling of the above exception, another exception occurred:

Traceback (most recent call last):
  File "C:\Users\Amna\AppData\Local\Programs\Python\Python38\lib\site-packages\flask\app.py", line 2447, in wsgi_app
    response = self.full_dispatch_request()
  File "C:\Users\Amna\AppData\Local\Programs\Python\Python38\lib\site-packages\flask\app.py", line 1952, in full_dispatch_request
    rv = self.handle_user_exception(e)
  File "C:\Users\Amna\AppData\Local\Programs\Python\Python38\lib\site-packages\flask\app.py", line 1821, in handle_user_exception
    reraise(exc_type, exc_value, tb)
  File "C:\Users\Amna\AppData\Local\Programs\Python\Python38\lib\site-packages\flask\_compat.py", line 39, in reraise
    raise value
  File "C:\Users\Amna\AppData\Local\Programs\Python\Python38\lib\site-packages\flask\app.py", line 1950, in full_dispatch_request
    rv = self.dispatch_request()
  File "C:\Users\Amna\AppData\Local\Programs\Python\Python38\lib\site-packages\flask\app.py", line 1936, in dispatch_request
    return self.view_functions[rule.endpoint](**req.view_args)
  File "app.py", line 348, in shows
    return render_template('pages/shows.html', shows=Show.query.all())
  File "C:\Users\Amna\AppData\Local\Programs\Python\Python38\lib\site-packages\flask_sqlalchemy\__init__.py", line 514, in __get__
    return type.query_class(mapper, session=self.sa.session())
  File "C:\Users\Amna\AppData\Local\Programs\Python\Python38\lib\site-packages\sqlalchemy\orm\scoping.py", line 78, in __call__
    return self.registry()
  File "C:\Users\Amna\AppData\Local\Programs\Python\Python38\lib\site-packages\sqlalchemy\util\_collections.py", line 1022, in __call__
    return self.registry.setdefault(key, self.createfunc())
  File "C:\Users\Amna\AppData\Local\Programs\Python\Python38\lib\site-packages\sqlalchemy\orm\session.py", line 3300, in __call__
    return self.class_(**local_kw)
  File "C:\Users\Amna\AppData\Local\Programs\Python\Python38\lib\site-packages\flask_sqlalchemy\__init__.py", line 137, in __init__
    track_modifications = app.config['SQLALCHEMY_TRACK_MODIFICATIONS']
KeyError: 'SQLALCHEMY_TRACK_MODIFICATIONS'
2020-10-28 13:13:38,881 ERROR: Exception on / [GET] [in C:\Users\Amna\AppData\Local\Programs\Python\Python38\lib\site-packages\flask\app.py:1891]
Traceback (most recent call last):
  File "C:\Users\Amna\AppData\Local\Programs\Python\Python38\lib\site-packages\sqlalchemy\util\_collections.py", line 1020, in __call__
    return self.registry[key]
KeyError: 3076

During handling of the above exception, another exception occurred:

Traceback (most recent call last):
  File "C:\Users\Amna\AppData\Local\Programs\Python\Python38\lib\site-packages\flask\app.py", line 2447, in wsgi_app
    response = self.full_dispatch_request()
  File "C:\Users\Amna\AppData\Local\Programs\Python\Python38\lib\site-packages\flask\app.py", line 1952, in full_dispatch_request
    rv = self.handle_user_exception(e)
  File "C:\Users\Amna\AppData\Local\Programs\Python\Python38\lib\site-packages\flask\app.py", line 1821, in handle_user_exception
    reraise(exc_type, exc_value, tb)
  File "C:\Users\Amna\AppData\Local\Programs\Python\Python38\lib\site-packages\flask\_compat.py", line 39, in reraise
    raise value
  File "C:\Users\Amna\AppData\Local\Programs\Python\Python38\lib\site-packages\flask\app.py", line 1950, in full_dispatch_request
    rv = self.dispatch_request()
  File "C:\Users\Amna\AppData\Local\Programs\Python\Python38\lib\site-packages\flask\app.py", line 1936, in dispatch_request
    return self.view_functions[rule.endpoint](**req.view_args)
  File "app.py", line 60, in index
    latestvenues=db.session.query(Venue).order_by(desc(Venue.id)).limit(10).all(),
  File "C:\Users\Amna\AppData\Local\Programs\Python\Python38\lib\site-packages\sqlalchemy\orm\scoping.py", line 163, in do
    return getattr(self.registry(), name)(*args, **kwargs)
  File "C:\Users\Amna\AppData\Local\Programs\Python\Python38\lib\site-packages\sqlalchemy\util\_collections.py", line 1022, in __call__
    return self.registry.setdefault(key, self.createfunc())
  File "C:\Users\Amna\AppData\Local\Programs\Python\Python38\lib\site-packages\sqlalchemy\orm\session.py", line 3300, in __call__
    return self.class_(**local_kw)
  File "C:\Users\Amna\AppData\Local\Programs\Python\Python38\lib\site-packages\flask_sqlalchemy\__init__.py", line 137, in __init__
    track_modifications = app.config['SQLALCHEMY_TRACK_MODIFICATIONS']
KeyError: 'SQLALCHEMY_TRACK_MODIFICATIONS'
2020-10-28 13:13:38,881 ERROR: Exception on / [GET] [in C:\Users\Amna\AppData\Local\Programs\Python\Python38\lib\site-packages\flask\app.py:1891]
Traceback (most recent call last):
  File "C:\Users\Amna\AppData\Local\Programs\Python\Python38\lib\site-packages\sqlalchemy\util\_collections.py", line 1020, in __call__
    return self.registry[key]
KeyError: 3076

During handling of the above exception, another exception occurred:

Traceback (most recent call last):
  File "C:\Users\Amna\AppData\Local\Programs\Python\Python38\lib\site-packages\flask\app.py", line 2447, in wsgi_app
    response = self.full_dispatch_request()
  File "C:\Users\Amna\AppData\Local\Programs\Python\Python38\lib\site-packages\flask\app.py", line 1952, in full_dispatch_request
    rv = self.handle_user_exception(e)
  File "C:\Users\Amna\AppData\Local\Programs\Python\Python38\lib\site-packages\flask\app.py", line 1821, in handle_user_exception
    reraise(exc_type, exc_value, tb)
  File "C:\Users\Amna\AppData\Local\Programs\Python\Python38\lib\site-packages\flask\_compat.py", line 39, in reraise
    raise value
  File "C:\Users\Amna\AppData\Local\Programs\Python\Python38\lib\site-packages\flask\app.py", line 1950, in full_dispatch_request
    rv = self.dispatch_request()
  File "C:\Users\Amna\AppData\Local\Programs\Python\Python38\lib\site-packages\flask\app.py", line 1936, in dispatch_request
    return self.view_functions[rule.endpoint](**req.view_args)
  File "app.py", line 60, in index
    latestvenues=db.session.query(Venue).order_by(desc(Venue.id)).limit(10).all(),
  File "C:\Users\Amna\AppData\Local\Programs\Python\Python38\lib\site-packages\sqlalchemy\orm\scoping.py", line 163, in do
    return getattr(self.registry(), name)(*args, **kwargs)
  File "C:\Users\Amna\AppData\Local\Programs\Python\Python38\lib\site-packages\sqlalchemy\util\_collections.py", line 1022, in __call__
    return self.registry.setdefault(key, self.createfunc())
  File "C:\Users\Amna\AppData\Local\Programs\Python\Python38\lib\site-packages\sqlalchemy\orm\session.py", line 3300, in __call__
    return self.class_(**local_kw)
  File "C:\Users\Amna\AppData\Local\Programs\Python\Python38\lib\site-packages\flask_sqlalchemy\__init__.py", line 137, in __init__
    track_modifications = app.config['SQLALCHEMY_TRACK_MODIFICATIONS']
KeyError: 'SQLALCHEMY_TRACK_MODIFICATIONS'
2020-10-28 13:13:40,189 ERROR: Exception on / [GET] [in C:\Users\Amna\AppData\Local\Programs\Python\Python38\lib\site-packages\flask\app.py:1891]
Traceback (most recent call last):
  File "C:\Users\Amna\AppData\Local\Programs\Python\Python38\lib\site-packages\sqlalchemy\util\_collections.py", line 1020, in __call__
    return self.registry[key]
KeyError: 11980

During handling of the above exception, another exception occurred:

Traceback (most recent call last):
  File "C:\Users\Amna\AppData\Local\Programs\Python\Python38\lib\site-packages\flask\app.py", line 2447, in wsgi_app
    response = self.full_dispatch_request()
  File "C:\Users\Amna\AppData\Local\Programs\Python\Python38\lib\site-packages\flask\app.py", line 1952, in full_dispatch_request
    rv = self.handle_user_exception(e)
  File "C:\Users\Amna\AppData\Local\Programs\Python\Python38\lib\site-packages\flask\app.py", line 1821, in handle_user_exception
    reraise(exc_type, exc_value, tb)
  File "C:\Users\Amna\AppData\Local\Programs\Python\Python38\lib\site-packages\flask\_compat.py", line 39, in reraise
    raise value
  File "C:\Users\Amna\AppData\Local\Programs\Python\Python38\lib\site-packages\flask\app.py", line 1950, in full_dispatch_request
    rv = self.dispatch_request()
  File "C:\Users\Amna\AppData\Local\Programs\Python\Python38\lib\site-packages\flask\app.py", line 1936, in dispatch_request
    return self.view_functions[rule.endpoint](**req.view_args)
  File "app.py", line 60, in index
    latestvenues=db.session.query(Venue).order_by(desc(Venue.id)).limit(10).all(),
  File "C:\Users\Amna\AppData\Local\Programs\Python\Python38\lib\site-packages\sqlalchemy\orm\scoping.py", line 163, in do
    return getattr(self.registry(), name)(*args, **kwargs)
  File "C:\Users\Amna\AppData\Local\Programs\Python\Python38\lib\site-packages\sqlalchemy\util\_collections.py", line 1022, in __call__
    return self.registry.setdefault(key, self.createfunc())
  File "C:\Users\Amna\AppData\Local\Programs\Python\Python38\lib\site-packages\sqlalchemy\orm\session.py", line 3300, in __call__
    return self.class_(**local_kw)
  File "C:\Users\Amna\AppData\Local\Programs\Python\Python38\lib\site-packages\flask_sqlalchemy\__init__.py", line 137, in __init__
    track_modifications = app.config['SQLALCHEMY_TRACK_MODIFICATIONS']
KeyError: 'SQLALCHEMY_TRACK_MODIFICATIONS'
2020-10-28 13:13:40,189 ERROR: Exception on / [GET] [in C:\Users\Amna\AppData\Local\Programs\Python\Python38\lib\site-packages\flask\app.py:1891]
Traceback (most recent call last):
  File "C:\Users\Amna\AppData\Local\Programs\Python\Python38\lib\site-packages\sqlalchemy\util\_collections.py", line 1020, in __call__
    return self.registry[key]
KeyError: 11980

During handling of the above exception, another exception occurred:

Traceback (most recent call last):
  File "C:\Users\Amna\AppData\Local\Programs\Python\Python38\lib\site-packages\flask\app.py", line 2447, in wsgi_app
    response = self.full_dispatch_request()
  File "C:\Users\Amna\AppData\Local\Programs\Python\Python38\lib\site-packages\flask\app.py", line 1952, in full_dispatch_request
    rv = self.handle_user_exception(e)
  File "C:\Users\Amna\AppData\Local\Programs\Python\Python38\lib\site-packages\flask\app.py", line 1821, in handle_user_exception
    reraise(exc_type, exc_value, tb)
  File "C:\Users\Amna\AppData\Local\Programs\Python\Python38\lib\site-packages\flask\_compat.py", line 39, in reraise
    raise value
  File "C:\Users\Amna\AppData\Local\Programs\Python\Python38\lib\site-packages\flask\app.py", line 1950, in full_dispatch_request
    rv = self.dispatch_request()
  File "C:\Users\Amna\AppData\Local\Programs\Python\Python38\lib\site-packages\flask\app.py", line 1936, in dispatch_request
    return self.view_functions[rule.endpoint](**req.view_args)
  File "app.py", line 60, in index
    latestvenues=db.session.query(Venue).order_by(desc(Venue.id)).limit(10).all(),
  File "C:\Users\Amna\AppData\Local\Programs\Python\Python38\lib\site-packages\sqlalchemy\orm\scoping.py", line 163, in do
    return getattr(self.registry(), name)(*args, **kwargs)
  File "C:\Users\Amna\AppData\Local\Programs\Python\Python38\lib\site-packages\sqlalchemy\util\_collections.py", line 1022, in __call__
    return self.registry.setdefault(key, self.createfunc())
  File "C:\Users\Amna\AppData\Local\Programs\Python\Python38\lib\site-packages\sqlalchemy\orm\session.py", line 3300, in __call__
    return self.class_(**local_kw)
  File "C:\Users\Amna\AppData\Local\Programs\Python\Python38\lib\site-packages\flask_sqlalchemy\__init__.py", line 137, in __init__
    track_modifications = app.config['SQLALCHEMY_TRACK_MODIFICATIONS']
KeyError: 'SQLALCHEMY_TRACK_MODIFICATIONS'
2020-10-28 13:20:13,066 ERROR: Exception on / [GET] [in C:\Users\Amna\AppData\Local\Programs\Python\Python38\lib\site-packages\flask\app.py:1891]
Traceback (most recent call last):
  File "C:\Users\Amna\AppData\Local\Programs\Python\Python38\lib\site-packages\sqlalchemy\util\_collections.py", line 1020, in __call__
    return self.registry[key]
KeyError: 4812

During handling of the above exception, another exception occurred:

Traceback (most recent call last):
  File "C:\Users\Amna\AppData\Local\Programs\Python\Python38\lib\site-packages\flask\app.py", line 2447, in wsgi_app
    response = self.full_dispatch_request()
  File "C:\Users\Amna\AppData\Local\Programs\Python\Python38\lib\site-packages\flask\app.py", line 1952, in full_dispatch_request
    rv = self.handle_user_exception(e)
  File "C:\Users\Amna\AppData\Local\Programs\Python\Python38\lib\site-packages\flask\app.py", line 1821, in handle_user_exception
    reraise(exc_type, exc_value, tb)
  File "C:\Users\Amna\AppData\Local\Programs\Python\Python38\lib\site-packages\flask\_compat.py", line 39, in reraise
    raise value
  File "C:\Users\Amna\AppData\Local\Programs\Python\Python38\lib\site-packages\flask\app.py", line 1950, in full_dispatch_request
    rv = self.dispatch_request()
  File "C:\Users\Amna\AppData\Local\Programs\Python\Python38\lib\site-packages\flask\app.py", line 1936, in dispatch_request
    return self.view_functions[rule.endpoint](**req.view_args)
  File "app.py", line 60, in index
    #  Venues
  File "C:\Users\Amna\AppData\Local\Programs\Python\Python38\lib\site-packages\sqlalchemy\orm\scoping.py", line 163, in do
    return getattr(self.registry(), name)(*args, **kwargs)
  File "C:\Users\Amna\AppData\Local\Programs\Python\Python38\lib\site-packages\sqlalchemy\util\_collections.py", line 1022, in __call__
    return self.registry.setdefault(key, self.createfunc())
  File "C:\Users\Amna\AppData\Local\Programs\Python\Python38\lib\site-packages\sqlalchemy\orm\session.py", line 3300, in __call__
    return self.class_(**local_kw)
  File "C:\Users\Amna\AppData\Local\Programs\Python\Python38\lib\site-packages\flask_sqlalchemy\__init__.py", line 137, in __init__
    track_modifications = app.config['SQLALCHEMY_TRACK_MODIFICATIONS']
KeyError: 'SQLALCHEMY_TRACK_MODIFICATIONS'
2020-10-28 13:20:13,066 ERROR: Exception on / [GET] [in C:\Users\Amna\AppData\Local\Programs\Python\Python38\lib\site-packages\flask\app.py:1891]
Traceback (most recent call last):
  File "C:\Users\Amna\AppData\Local\Programs\Python\Python38\lib\site-packages\sqlalchemy\util\_collections.py", line 1020, in __call__
    return self.registry[key]
KeyError: 4812

During handling of the above exception, another exception occurred:

Traceback (most recent call last):
  File "C:\Users\Amna\AppData\Local\Programs\Python\Python38\lib\site-packages\flask\app.py", line 2447, in wsgi_app
    response = self.full_dispatch_request()
  File "C:\Users\Amna\AppData\Local\Programs\Python\Python38\lib\site-packages\flask\app.py", line 1952, in full_dispatch_request
    rv = self.handle_user_exception(e)
  File "C:\Users\Amna\AppData\Local\Programs\Python\Python38\lib\site-packages\flask\app.py", line 1821, in handle_user_exception
    reraise(exc_type, exc_value, tb)
  File "C:\Users\Amna\AppData\Local\Programs\Python\Python38\lib\site-packages\flask\_compat.py", line 39, in reraise
    raise value
  File "C:\Users\Amna\AppData\Local\Programs\Python\Python38\lib\site-packages\flask\app.py", line 1950, in full_dispatch_request
    rv = self.dispatch_request()
  File "C:\Users\Amna\AppData\Local\Programs\Python\Python38\lib\site-packages\flask\app.py", line 1936, in dispatch_request
    return self.view_functions[rule.endpoint](**req.view_args)
  File "app.py", line 60, in index
    #  Venues
  File "C:\Users\Amna\AppData\Local\Programs\Python\Python38\lib\site-packages\sqlalchemy\orm\scoping.py", line 163, in do
    return getattr(self.registry(), name)(*args, **kwargs)
  File "C:\Users\Amna\AppData\Local\Programs\Python\Python38\lib\site-packages\sqlalchemy\util\_collections.py", line 1022, in __call__
    return self.registry.setdefault(key, self.createfunc())
  File "C:\Users\Amna\AppData\Local\Programs\Python\Python38\lib\site-packages\sqlalchemy\orm\session.py", line 3300, in __call__
    return self.class_(**local_kw)
  File "C:\Users\Amna\AppData\Local\Programs\Python\Python38\lib\site-packages\flask_sqlalchemy\__init__.py", line 137, in __init__
    track_modifications = app.config['SQLALCHEMY_TRACK_MODIFICATIONS']
KeyError: 'SQLALCHEMY_TRACK_MODIFICATIONS'
2020-10-28 13:20:14,702 ERROR: Exception on /venues [GET] [in C:\Users\Amna\AppData\Local\Programs\Python\Python38\lib\site-packages\flask\app.py:1891]
Traceback (most recent call last):
  File "C:\Users\Amna\AppData\Local\Programs\Python\Python38\lib\site-packages\sqlalchemy\util\_collections.py", line 1020, in __call__
    return self.registry[key]
KeyError: 10884

During handling of the above exception, another exception occurred:

Traceback (most recent call last):
  File "C:\Users\Amna\AppData\Local\Programs\Python\Python38\lib\site-packages\flask\app.py", line 2447, in wsgi_app
    response = self.full_dispatch_request()
  File "C:\Users\Amna\AppData\Local\Programs\Python\Python38\lib\site-packages\flask\app.py", line 1952, in full_dispatch_request
    rv = self.handle_user_exception(e)
  File "C:\Users\Amna\AppData\Local\Programs\Python\Python38\lib\site-packages\flask\app.py", line 1821, in handle_user_exception
    reraise(exc_type, exc_value, tb)
  File "C:\Users\Amna\AppData\Local\Programs\Python\Python38\lib\site-packages\flask\_compat.py", line 39, in reraise
    raise value
  File "C:\Users\Amna\AppData\Local\Programs\Python\Python38\lib\site-packages\flask\app.py", line 1950, in full_dispatch_request
    rv = self.dispatch_request()
  File "C:\Users\Amna\AppData\Local\Programs\Python\Python38\lib\site-packages\flask\app.py", line 1936, in dispatch_request
    return self.view_functions[rule.endpoint](**req.view_args)
  File "app.py", line 69, in venues
    dic={}
  File "C:\Users\Amna\AppData\Local\Programs\Python\Python38\lib\site-packages\flask_sqlalchemy\__init__.py", line 514, in __get__
    return type.query_class(mapper, session=self.sa.session())
  File "C:\Users\Amna\AppData\Local\Programs\Python\Python38\lib\site-packages\sqlalchemy\orm\scoping.py", line 78, in __call__
    return self.registry()
  File "C:\Users\Amna\AppData\Local\Programs\Python\Python38\lib\site-packages\sqlalchemy\util\_collections.py", line 1022, in __call__
    return self.registry.setdefault(key, self.createfunc())
  File "C:\Users\Amna\AppData\Local\Programs\Python\Python38\lib\site-packages\sqlalchemy\orm\session.py", line 3300, in __call__
    return self.class_(**local_kw)
  File "C:\Users\Amna\AppData\Local\Programs\Python\Python38\lib\site-packages\flask_sqlalchemy\__init__.py", line 137, in __init__
    track_modifications = app.config['SQLALCHEMY_TRACK_MODIFICATIONS']
KeyError: 'SQLALCHEMY_TRACK_MODIFICATIONS'
2020-10-28 13:20:14,702 ERROR: Exception on /venues [GET] [in C:\Users\Amna\AppData\Local\Programs\Python\Python38\lib\site-packages\flask\app.py:1891]
Traceback (most recent call last):
  File "C:\Users\Amna\AppData\Local\Programs\Python\Python38\lib\site-packages\sqlalchemy\util\_collections.py", line 1020, in __call__
    return self.registry[key]
KeyError: 10884

During handling of the above exception, another exception occurred:

Traceback (most recent call last):
  File "C:\Users\Amna\AppData\Local\Programs\Python\Python38\lib\site-packages\flask\app.py", line 2447, in wsgi_app
    response = self.full_dispatch_request()
  File "C:\Users\Amna\AppData\Local\Programs\Python\Python38\lib\site-packages\flask\app.py", line 1952, in full_dispatch_request
    rv = self.handle_user_exception(e)
  File "C:\Users\Amna\AppData\Local\Programs\Python\Python38\lib\site-packages\flask\app.py", line 1821, in handle_user_exception
    reraise(exc_type, exc_value, tb)
  File "C:\Users\Amna\AppData\Local\Programs\Python\Python38\lib\site-packages\flask\_compat.py", line 39, in reraise
    raise value
  File "C:\Users\Amna\AppData\Local\Programs\Python\Python38\lib\site-packages\flask\app.py", line 1950, in full_dispatch_request
    rv = self.dispatch_request()
  File "C:\Users\Amna\AppData\Local\Programs\Python\Python38\lib\site-packages\flask\app.py", line 1936, in dispatch_request
    return self.view_functions[rule.endpoint](**req.view_args)
  File "app.py", line 69, in venues
    dic={}
  File "C:\Users\Amna\AppData\Local\Programs\Python\Python38\lib\site-packages\flask_sqlalchemy\__init__.py", line 514, in __get__
    return type.query_class(mapper, session=self.sa.session())
  File "C:\Users\Amna\AppData\Local\Programs\Python\Python38\lib\site-packages\sqlalchemy\orm\scoping.py", line 78, in __call__
    return self.registry()
  File "C:\Users\Amna\AppData\Local\Programs\Python\Python38\lib\site-packages\sqlalchemy\util\_collections.py", line 1022, in __call__
    return self.registry.setdefault(key, self.createfunc())
  File "C:\Users\Amna\AppData\Local\Programs\Python\Python38\lib\site-packages\sqlalchemy\orm\session.py", line 3300, in __call__
    return self.class_(**local_kw)
  File "C:\Users\Amna\AppData\Local\Programs\Python\Python38\lib\site-packages\flask_sqlalchemy\__init__.py", line 137, in __init__
    track_modifications = app.config['SQLALCHEMY_TRACK_MODIFICATIONS']
KeyError: 'SQLALCHEMY_TRACK_MODIFICATIONS'
2020-10-28 13:20:15,780 ERROR: Exception on /artists [GET] [in C:\Users\Amna\AppData\Local\Programs\Python\Python38\lib\site-packages\flask\app.py:1891]
Traceback (most recent call last):
  File "C:\Users\Amna\AppData\Local\Programs\Python\Python38\lib\site-packages\sqlalchemy\util\_collections.py", line 1020, in __call__
    return self.registry[key]
KeyError: 9332

During handling of the above exception, another exception occurred:

Traceback (most recent call last):
  File "C:\Users\Amna\AppData\Local\Programs\Python\Python38\lib\site-packages\flask\app.py", line 2447, in wsgi_app
    response = self.full_dispatch_request()
  File "C:\Users\Amna\AppData\Local\Programs\Python\Python38\lib\site-packages\flask\app.py", line 1952, in full_dispatch_request
    rv = self.handle_user_exception(e)
  File "C:\Users\Amna\AppData\Local\Programs\Python\Python38\lib\site-packages\flask\app.py", line 1821, in handle_user_exception
    reraise(exc_type, exc_value, tb)
  File "C:\Users\Amna\AppData\Local\Programs\Python\Python38\lib\site-packages\flask\_compat.py", line 39, in reraise
    raise value
  File "C:\Users\Amna\AppData\Local\Programs\Python\Python38\lib\site-packages\flask\app.py", line 1950, in full_dispatch_request
    rv = self.dispatch_request()
  File "C:\Users\Amna\AppData\Local\Programs\Python\Python38\lib\site-packages\flask\app.py", line 1936, in dispatch_request
    return self.view_functions[rule.endpoint](**req.view_args)
  File "app.py", line 187, in artists
    searchword=request.form.get("search_term")
  File "C:\Users\Amna\AppData\Local\Programs\Python\Python38\lib\site-packages\flask_sqlalchemy\__init__.py", line 514, in __get__
    return type.query_class(mapper, session=self.sa.session())
  File "C:\Users\Amna\AppData\Local\Programs\Python\Python38\lib\site-packages\sqlalchemy\orm\scoping.py", line 78, in __call__
    return self.registry()
  File "C:\Users\Amna\AppData\Local\Programs\Python\Python38\lib\site-packages\sqlalchemy\util\_collections.py", line 1022, in __call__
    return self.registry.setdefault(key, self.createfunc())
  File "C:\Users\Amna\AppData\Local\Programs\Python\Python38\lib\site-packages\sqlalchemy\orm\session.py", line 3300, in __call__
    return self.class_(**local_kw)
  File "C:\Users\Amna\AppData\Local\Programs\Python\Python38\lib\site-packages\flask_sqlalchemy\__init__.py", line 137, in __init__
    track_modifications = app.config['SQLALCHEMY_TRACK_MODIFICATIONS']
KeyError: 'SQLALCHEMY_TRACK_MODIFICATIONS'
2020-10-28 13:20:15,780 ERROR: Exception on /artists [GET] [in C:\Users\Amna\AppData\Local\Programs\Python\Python38\lib\site-packages\flask\app.py:1891]
Traceback (most recent call last):
  File "C:\Users\Amna\AppData\Local\Programs\Python\Python38\lib\site-packages\sqlalchemy\util\_collections.py", line 1020, in __call__
    return self.registry[key]
KeyError: 9332

During handling of the above exception, another exception occurred:

Traceback (most recent call last):
  File "C:\Users\Amna\AppData\Local\Programs\Python\Python38\lib\site-packages\flask\app.py", line 2447, in wsgi_app
    response = self.full_dispatch_request()
  File "C:\Users\Amna\AppData\Local\Programs\Python\Python38\lib\site-packages\flask\app.py", line 1952, in full_dispatch_request
    rv = self.handle_user_exception(e)
  File "C:\Users\Amna\AppData\Local\Programs\Python\Python38\lib\site-packages\flask\app.py", line 1821, in handle_user_exception
    reraise(exc_type, exc_value, tb)
  File "C:\Users\Amna\AppData\Local\Programs\Python\Python38\lib\site-packages\flask\_compat.py", line 39, in reraise
    raise value
  File "C:\Users\Amna\AppData\Local\Programs\Python\Python38\lib\site-packages\flask\app.py", line 1950, in full_dispatch_request
    rv = self.dispatch_request()
  File "C:\Users\Amna\AppData\Local\Programs\Python\Python38\lib\site-packages\flask\app.py", line 1936, in dispatch_request
    return self.view_functions[rule.endpoint](**req.view_args)
  File "app.py", line 187, in artists
    searchword=request.form.get("search_term")
  File "C:\Users\Amna\AppData\Local\Programs\Python\Python38\lib\site-packages\flask_sqlalchemy\__init__.py", line 514, in __get__
    return type.query_class(mapper, session=self.sa.session())
  File "C:\Users\Amna\AppData\Local\Programs\Python\Python38\lib\site-packages\sqlalchemy\orm\scoping.py", line 78, in __call__
    return self.registry()
  File "C:\Users\Amna\AppData\Local\Programs\Python\Python38\lib\site-packages\sqlalchemy\util\_collections.py", line 1022, in __call__
    return self.registry.setdefault(key, self.createfunc())
  File "C:\Users\Amna\AppData\Local\Programs\Python\Python38\lib\site-packages\sqlalchemy\orm\session.py", line 3300, in __call__
    return self.class_(**local_kw)
  File "C:\Users\Amna\AppData\Local\Programs\Python\Python38\lib\site-packages\flask_sqlalchemy\__init__.py", line 137, in __init__
    track_modifications = app.config['SQLALCHEMY_TRACK_MODIFICATIONS']
KeyError: 'SQLALCHEMY_TRACK_MODIFICATIONS'
2020-10-28 13:20:16,685 ERROR: Exception on /shows [GET] [in C:\Users\Amna\AppData\Local\Programs\Python\Python38\lib\site-packages\flask\app.py:1891]
Traceback (most recent call last):
  File "C:\Users\Amna\AppData\Local\Programs\Python\Python38\lib\site-packages\sqlalchemy\util\_collections.py", line 1020, in __call__
    return self.registry[key]
KeyError: 2296

During handling of the above exception, another exception occurred:

Traceback (most recent call last):
  File "C:\Users\Amna\AppData\Local\Programs\Python\Python38\lib\site-packages\flask\app.py", line 2447, in wsgi_app
    response = self.full_dispatch_request()
  File "C:\Users\Amna\AppData\Local\Programs\Python\Python38\lib\site-packages\flask\app.py", line 1952, in full_dispatch_request
    rv = self.handle_user_exception(e)
  File "C:\Users\Amna\AppData\Local\Programs\Python\Python38\lib\site-packages\flask\app.py", line 1821, in handle_user_exception
    reraise(exc_type, exc_value, tb)
  File "C:\Users\Amna\AppData\Local\Programs\Python\Python38\lib\site-packages\flask\_compat.py", line 39, in reraise
    raise value
  File "C:\Users\Amna\AppData\Local\Programs\Python\Python38\lib\site-packages\flask\app.py", line 1950, in full_dispatch_request
    rv = self.dispatch_request()
  File "C:\Users\Amna\AppData\Local\Programs\Python\Python38\lib\site-packages\flask\app.py", line 1936, in dispatch_request
    return self.view_functions[rule.endpoint](**req.view_args)
  File "app.py", line 348, in shows
    # renders form. do not touch.
  File "C:\Users\Amna\AppData\Local\Programs\Python\Python38\lib\site-packages\flask_sqlalchemy\__init__.py", line 514, in __get__
    return type.query_class(mapper, session=self.sa.session())
  File "C:\Users\Amna\AppData\Local\Programs\Python\Python38\lib\site-packages\sqlalchemy\orm\scoping.py", line 78, in __call__
    return self.registry()
  File "C:\Users\Amna\AppData\Local\Programs\Python\Python38\lib\site-packages\sqlalchemy\util\_collections.py", line 1022, in __call__
    return self.registry.setdefault(key, self.createfunc())
  File "C:\Users\Amna\AppData\Local\Programs\Python\Python38\lib\site-packages\sqlalchemy\orm\session.py", line 3300, in __call__
    return self.class_(**local_kw)
  File "C:\Users\Amna\AppData\Local\Programs\Python\Python38\lib\site-packages\flask_sqlalchemy\__init__.py", line 137, in __init__
    track_modifications = app.config['SQLALCHEMY_TRACK_MODIFICATIONS']
KeyError: 'SQLALCHEMY_TRACK_MODIFICATIONS'
2020-10-28 13:20:16,685 ERROR: Exception on /shows [GET] [in C:\Users\Amna\AppData\Local\Programs\Python\Python38\lib\site-packages\flask\app.py:1891]
Traceback (most recent call last):
  File "C:\Users\Amna\AppData\Local\Programs\Python\Python38\lib\site-packages\sqlalchemy\util\_collections.py", line 1020, in __call__
    return self.registry[key]
KeyError: 2296

During handling of the above exception, another exception occurred:

Traceback (most recent call last):
  File "C:\Users\Amna\AppData\Local\Programs\Python\Python38\lib\site-packages\flask\app.py", line 2447, in wsgi_app
    response = self.full_dispatch_request()
  File "C:\Users\Amna\AppData\Local\Programs\Python\Python38\lib\site-packages\flask\app.py", line 1952, in full_dispatch_request
    rv = self.handle_user_exception(e)
  File "C:\Users\Amna\AppData\Local\Programs\Python\Python38\lib\site-packages\flask\app.py", line 1821, in handle_user_exception
    reraise(exc_type, exc_value, tb)
  File "C:\Users\Amna\AppData\Local\Programs\Python\Python38\lib\site-packages\flask\_compat.py", line 39, in reraise
    raise value
  File "C:\Users\Amna\AppData\Local\Programs\Python\Python38\lib\site-packages\flask\app.py", line 1950, in full_dispatch_request
    rv = self.dispatch_request()
  File "C:\Users\Amna\AppData\Local\Programs\Python\Python38\lib\site-packages\flask\app.py", line 1936, in dispatch_request
    return self.view_functions[rule.endpoint](**req.view_args)
  File "app.py", line 348, in shows
    # renders form. do not touch.
  File "C:\Users\Amna\AppData\Local\Programs\Python\Python38\lib\site-packages\flask_sqlalchemy\__init__.py", line 514, in __get__
    return type.query_class(mapper, session=self.sa.session())
  File "C:\Users\Amna\AppData\Local\Programs\Python\Python38\lib\site-packages\sqlalchemy\orm\scoping.py", line 78, in __call__
    return self.registry()
  File "C:\Users\Amna\AppData\Local\Programs\Python\Python38\lib\site-packages\sqlalchemy\util\_collections.py", line 1022, in __call__
    return self.registry.setdefault(key, self.createfunc())
  File "C:\Users\Amna\AppData\Local\Programs\Python\Python38\lib\site-packages\sqlalchemy\orm\session.py", line 3300, in __call__
    return self.class_(**local_kw)
  File "C:\Users\Amna\AppData\Local\Programs\Python\Python38\lib\site-packages\flask_sqlalchemy\__init__.py", line 137, in __init__
    track_modifications = app.config['SQLALCHEMY_TRACK_MODIFICATIONS']
KeyError: 'SQLALCHEMY_TRACK_MODIFICATIONS'
2020-10-28 13:20:19,320 ERROR: Exception on /shows [GET] [in C:\Users\Amna\AppData\Local\Programs\Python\Python38\lib\site-packages\flask\app.py:1891]
Traceback (most recent call last):
  File "C:\Users\Amna\AppData\Local\Programs\Python\Python38\lib\site-packages\sqlalchemy\util\_collections.py", line 1020, in __call__
    return self.registry[key]
KeyError: 3948

During handling of the above exception, another exception occurred:

Traceback (most recent call last):
  File "C:\Users\Amna\AppData\Local\Programs\Python\Python38\lib\site-packages\flask\app.py", line 2447, in wsgi_app
    response = self.full_dispatch_request()
  File "C:\Users\Amna\AppData\Local\Programs\Python\Python38\lib\site-packages\flask\app.py", line 1952, in full_dispatch_request
    rv = self.handle_user_exception(e)
  File "C:\Users\Amna\AppData\Local\Programs\Python\Python38\lib\site-packages\flask\app.py", line 1821, in handle_user_exception
    reraise(exc_type, exc_value, tb)
  File "C:\Users\Amna\AppData\Local\Programs\Python\Python38\lib\site-packages\flask\_compat.py", line 39, in reraise
    raise value
  File "C:\Users\Amna\AppData\Local\Programs\Python\Python38\lib\site-packages\flask\app.py", line 1950, in full_dispatch_request
    rv = self.dispatch_request()
  File "C:\Users\Amna\AppData\Local\Programs\Python\Python38\lib\site-packages\flask\app.py", line 1936, in dispatch_request
    return self.view_functions[rule.endpoint](**req.view_args)
  File "app.py", line 348, in shows
    # renders form. do not touch.
  File "C:\Users\Amna\AppData\Local\Programs\Python\Python38\lib\site-packages\flask_sqlalchemy\__init__.py", line 514, in __get__
    return type.query_class(mapper, session=self.sa.session())
  File "C:\Users\Amna\AppData\Local\Programs\Python\Python38\lib\site-packages\sqlalchemy\orm\scoping.py", line 78, in __call__
    return self.registry()
  File "C:\Users\Amna\AppData\Local\Programs\Python\Python38\lib\site-packages\sqlalchemy\util\_collections.py", line 1022, in __call__
    return self.registry.setdefault(key, self.createfunc())
  File "C:\Users\Amna\AppData\Local\Programs\Python\Python38\lib\site-packages\sqlalchemy\orm\session.py", line 3300, in __call__
    return self.class_(**local_kw)
  File "C:\Users\Amna\AppData\Local\Programs\Python\Python38\lib\site-packages\flask_sqlalchemy\__init__.py", line 137, in __init__
    track_modifications = app.config['SQLALCHEMY_TRACK_MODIFICATIONS']
KeyError: 'SQLALCHEMY_TRACK_MODIFICATIONS'
2020-10-28 13:20:19,320 ERROR: Exception on /shows [GET] [in C:\Users\Amna\AppData\Local\Programs\Python\Python38\lib\site-packages\flask\app.py:1891]
Traceback (most recent call last):
  File "C:\Users\Amna\AppData\Local\Programs\Python\Python38\lib\site-packages\sqlalchemy\util\_collections.py", line 1020, in __call__
    return self.registry[key]
KeyError: 3948

During handling of the above exception, another exception occurred:

Traceback (most recent call last):
  File "C:\Users\Amna\AppData\Local\Programs\Python\Python38\lib\site-packages\flask\app.py", line 2447, in wsgi_app
    response = self.full_dispatch_request()
  File "C:\Users\Amna\AppData\Local\Programs\Python\Python38\lib\site-packages\flask\app.py", line 1952, in full_dispatch_request
    rv = self.handle_user_exception(e)
  File "C:\Users\Amna\AppData\Local\Programs\Python\Python38\lib\site-packages\flask\app.py", line 1821, in handle_user_exception
    reraise(exc_type, exc_value, tb)
  File "C:\Users\Amna\AppData\Local\Programs\Python\Python38\lib\site-packages\flask\_compat.py", line 39, in reraise
    raise value
  File "C:\Users\Amna\AppData\Local\Programs\Python\Python38\lib\site-packages\flask\app.py", line 1950, in full_dispatch_request
    rv = self.dispatch_request()
  File "C:\Users\Amna\AppData\Local\Programs\Python\Python38\lib\site-packages\flask\app.py", line 1936, in dispatch_request
    return self.view_functions[rule.endpoint](**req.view_args)
  File "app.py", line 348, in shows
    # renders form. do not touch.
  File "C:\Users\Amna\AppData\Local\Programs\Python\Python38\lib\site-packages\flask_sqlalchemy\__init__.py", line 514, in __get__
    return type.query_class(mapper, session=self.sa.session())
  File "C:\Users\Amna\AppData\Local\Programs\Python\Python38\lib\site-packages\sqlalchemy\orm\scoping.py", line 78, in __call__
    return self.registry()
  File "C:\Users\Amna\AppData\Local\Programs\Python\Python38\lib\site-packages\sqlalchemy\util\_collections.py", line 1022, in __call__
    return self.registry.setdefault(key, self.createfunc())
  File "C:\Users\Amna\AppData\Local\Programs\Python\Python38\lib\site-packages\sqlalchemy\orm\session.py", line 3300, in __call__
    return self.class_(**local_kw)
  File "C:\Users\Amna\AppData\Local\Programs\Python\Python38\lib\site-packages\flask_sqlalchemy\__init__.py", line 137, in __init__
    track_modifications = app.config['SQLALCHEMY_TRACK_MODIFICATIONS']
KeyError: 'SQLALCHEMY_TRACK_MODIFICATIONS'
2020-10-28 13:20:20,679 ERROR: Exception on / [GET] [in C:\Users\Amna\AppData\Local\Programs\Python\Python38\lib\site-packages\flask\app.py:1891]
Traceback (most recent call last):
  File "C:\Users\Amna\AppData\Local\Programs\Python\Python38\lib\site-packages\sqlalchemy\util\_collections.py", line 1020, in __call__
    return self.registry[key]
KeyError: 3268

During handling of the above exception, another exception occurred:

Traceback (most recent call last):
  File "C:\Users\Amna\AppData\Local\Programs\Python\Python38\lib\site-packages\flask\app.py", line 2447, in wsgi_app
    response = self.full_dispatch_request()
  File "C:\Users\Amna\AppData\Local\Programs\Python\Python38\lib\site-packages\flask\app.py", line 1952, in full_dispatch_request
    rv = self.handle_user_exception(e)
  File "C:\Users\Amna\AppData\Local\Programs\Python\Python38\lib\site-packages\flask\app.py", line 1821, in handle_user_exception
    reraise(exc_type, exc_value, tb)
  File "C:\Users\Amna\AppData\Local\Programs\Python\Python38\lib\site-packages\flask\_compat.py", line 39, in reraise
    raise value
  File "C:\Users\Amna\AppData\Local\Programs\Python\Python38\lib\site-packages\flask\app.py", line 1950, in full_dispatch_request
    rv = self.dispatch_request()
  File "C:\Users\Amna\AppData\Local\Programs\Python\Python38\lib\site-packages\flask\app.py", line 1936, in dispatch_request
    return self.view_functions[rule.endpoint](**req.view_args)
  File "app.py", line 60, in index
    #  Venues
  File "C:\Users\Amna\AppData\Local\Programs\Python\Python38\lib\site-packages\sqlalchemy\orm\scoping.py", line 163, in do
    return getattr(self.registry(), name)(*args, **kwargs)
  File "C:\Users\Amna\AppData\Local\Programs\Python\Python38\lib\site-packages\sqlalchemy\util\_collections.py", line 1022, in __call__
    return self.registry.setdefault(key, self.createfunc())
  File "C:\Users\Amna\AppData\Local\Programs\Python\Python38\lib\site-packages\sqlalchemy\orm\session.py", line 3300, in __call__
    return self.class_(**local_kw)
  File "C:\Users\Amna\AppData\Local\Programs\Python\Python38\lib\site-packages\flask_sqlalchemy\__init__.py", line 137, in __init__
    track_modifications = app.config['SQLALCHEMY_TRACK_MODIFICATIONS']
KeyError: 'SQLALCHEMY_TRACK_MODIFICATIONS'
2020-10-28 13:20:20,679 ERROR: Exception on / [GET] [in C:\Users\Amna\AppData\Local\Programs\Python\Python38\lib\site-packages\flask\app.py:1891]
Traceback (most recent call last):
  File "C:\Users\Amna\AppData\Local\Programs\Python\Python38\lib\site-packages\sqlalchemy\util\_collections.py", line 1020, in __call__
    return self.registry[key]
KeyError: 3268

During handling of the above exception, another exception occurred:

Traceback (most recent call last):
  File "C:\Users\Amna\AppData\Local\Programs\Python\Python38\lib\site-packages\flask\app.py", line 2447, in wsgi_app
    response = self.full_dispatch_request()
  File "C:\Users\Amna\AppData\Local\Programs\Python\Python38\lib\site-packages\flask\app.py", line 1952, in full_dispatch_request
    rv = self.handle_user_exception(e)
  File "C:\Users\Amna\AppData\Local\Programs\Python\Python38\lib\site-packages\flask\app.py", line 1821, in handle_user_exception
    reraise(exc_type, exc_value, tb)
  File "C:\Users\Amna\AppData\Local\Programs\Python\Python38\lib\site-packages\flask\_compat.py", line 39, in reraise
    raise value
  File "C:\Users\Amna\AppData\Local\Programs\Python\Python38\lib\site-packages\flask\app.py", line 1950, in full_dispatch_request
    rv = self.dispatch_request()
  File "C:\Users\Amna\AppData\Local\Programs\Python\Python38\lib\site-packages\flask\app.py", line 1936, in dispatch_request
    return self.view_functions[rule.endpoint](**req.view_args)
  File "app.py", line 60, in index
    #  Venues
  File "C:\Users\Amna\AppData\Local\Programs\Python\Python38\lib\site-packages\sqlalchemy\orm\scoping.py", line 163, in do
    return getattr(self.registry(), name)(*args, **kwargs)
  File "C:\Users\Amna\AppData\Local\Programs\Python\Python38\lib\site-packages\sqlalchemy\util\_collections.py", line 1022, in __call__
    return self.registry.setdefault(key, self.createfunc())
  File "C:\Users\Amna\AppData\Local\Programs\Python\Python38\lib\site-packages\sqlalchemy\orm\session.py", line 3300, in __call__
    return self.class_(**local_kw)
  File "C:\Users\Amna\AppData\Local\Programs\Python\Python38\lib\site-packages\flask_sqlalchemy\__init__.py", line 137, in __init__
    track_modifications = app.config['SQLALCHEMY_TRACK_MODIFICATIONS']
KeyError: 'SQLALCHEMY_TRACK_MODIFICATIONS'
2020-10-28 13:20:21,603 ERROR: Exception on /venues [GET] [in C:\Users\Amna\AppData\Local\Programs\Python\Python38\lib\site-packages\flask\app.py:1891]
Traceback (most recent call last):
  File "C:\Users\Amna\AppData\Local\Programs\Python\Python38\lib\site-packages\sqlalchemy\util\_collections.py", line 1020, in __call__
    return self.registry[key]
KeyError: 5008

During handling of the above exception, another exception occurred:

Traceback (most recent call last):
  File "C:\Users\Amna\AppData\Local\Programs\Python\Python38\lib\site-packages\flask\app.py", line 2447, in wsgi_app
    response = self.full_dispatch_request()
  File "C:\Users\Amna\AppData\Local\Programs\Python\Python38\lib\site-packages\flask\app.py", line 1952, in full_dispatch_request
    rv = self.handle_user_exception(e)
  File "C:\Users\Amna\AppData\Local\Programs\Python\Python38\lib\site-packages\flask\app.py", line 1821, in handle_user_exception
    reraise(exc_type, exc_value, tb)
  File "C:\Users\Amna\AppData\Local\Programs\Python\Python38\lib\site-packages\flask\_compat.py", line 39, in reraise
    raise value
  File "C:\Users\Amna\AppData\Local\Programs\Python\Python38\lib\site-packages\flask\app.py", line 1950, in full_dispatch_request
    rv = self.dispatch_request()
  File "C:\Users\Amna\AppData\Local\Programs\Python\Python38\lib\site-packages\flask\app.py", line 1936, in dispatch_request
    return self.view_functions[rule.endpoint](**req.view_args)
  File "app.py", line 69, in venues
    dic={}
  File "C:\Users\Amna\AppData\Local\Programs\Python\Python38\lib\site-packages\flask_sqlalchemy\__init__.py", line 514, in __get__
    return type.query_class(mapper, session=self.sa.session())
  File "C:\Users\Amna\AppData\Local\Programs\Python\Python38\lib\site-packages\sqlalchemy\orm\scoping.py", line 78, in __call__
    return self.registry()
  File "C:\Users\Amna\AppData\Local\Programs\Python\Python38\lib\site-packages\sqlalchemy\util\_collections.py", line 1022, in __call__
    return self.registry.setdefault(key, self.createfunc())
  File "C:\Users\Amna\AppData\Local\Programs\Python\Python38\lib\site-packages\sqlalchemy\orm\session.py", line 3300, in __call__
    return self.class_(**local_kw)
  File "C:\Users\Amna\AppData\Local\Programs\Python\Python38\lib\site-packages\flask_sqlalchemy\__init__.py", line 137, in __init__
    track_modifications = app.config['SQLALCHEMY_TRACK_MODIFICATIONS']
KeyError: 'SQLALCHEMY_TRACK_MODIFICATIONS'
2020-10-28 13:20:21,603 ERROR: Exception on /venues [GET] [in C:\Users\Amna\AppData\Local\Programs\Python\Python38\lib\site-packages\flask\app.py:1891]
Traceback (most recent call last):
  File "C:\Users\Amna\AppData\Local\Programs\Python\Python38\lib\site-packages\sqlalchemy\util\_collections.py", line 1020, in __call__
    return self.registry[key]
KeyError: 5008

During handling of the above exception, another exception occurred:

Traceback (most recent call last):
  File "C:\Users\Amna\AppData\Local\Programs\Python\Python38\lib\site-packages\flask\app.py", line 2447, in wsgi_app
    response = self.full_dispatch_request()
  File "C:\Users\Amna\AppData\Local\Programs\Python\Python38\lib\site-packages\flask\app.py", line 1952, in full_dispatch_request
    rv = self.handle_user_exception(e)
  File "C:\Users\Amna\AppData\Local\Programs\Python\Python38\lib\site-packages\flask\app.py", line 1821, in handle_user_exception
    reraise(exc_type, exc_value, tb)
  File "C:\Users\Amna\AppData\Local\Programs\Python\Python38\lib\site-packages\flask\_compat.py", line 39, in reraise
    raise value
  File "C:\Users\Amna\AppData\Local\Programs\Python\Python38\lib\site-packages\flask\app.py", line 1950, in full_dispatch_request
    rv = self.dispatch_request()
  File "C:\Users\Amna\AppData\Local\Programs\Python\Python38\lib\site-packages\flask\app.py", line 1936, in dispatch_request
    return self.view_functions[rule.endpoint](**req.view_args)
  File "app.py", line 69, in venues
    dic={}
  File "C:\Users\Amna\AppData\Local\Programs\Python\Python38\lib\site-packages\flask_sqlalchemy\__init__.py", line 514, in __get__
    return type.query_class(mapper, session=self.sa.session())
  File "C:\Users\Amna\AppData\Local\Programs\Python\Python38\lib\site-packages\sqlalchemy\orm\scoping.py", line 78, in __call__
    return self.registry()
  File "C:\Users\Amna\AppData\Local\Programs\Python\Python38\lib\site-packages\sqlalchemy\util\_collections.py", line 1022, in __call__
    return self.registry.setdefault(key, self.createfunc())
  File "C:\Users\Amna\AppData\Local\Programs\Python\Python38\lib\site-packages\sqlalchemy\orm\session.py", line 3300, in __call__
    return self.class_(**local_kw)
  File "C:\Users\Amna\AppData\Local\Programs\Python\Python38\lib\site-packages\flask_sqlalchemy\__init__.py", line 137, in __init__
    track_modifications = app.config['SQLALCHEMY_TRACK_MODIFICATIONS']
KeyError: 'SQLALCHEMY_TRACK_MODIFICATIONS'
2020-10-28 13:20:48,296 INFO: errors [in C:\Users\Amna\class-demos\fyyur\starter_code\app.py:391]
2020-10-28 13:20:48,325 INFO: errors [in app.py:391]
2020-10-28 13:20:48,325 INFO: errors [in app.py:391]
2020-10-28 13:20:52,411 ERROR: Exception on /venues [GET] [in C:\Users\Amna\AppData\Local\Programs\Python\Python38\lib\site-packages\flask\app.py:1891]
Traceback (most recent call last):
  File "C:\Users\Amna\AppData\Local\Programs\Python\Python38\lib\site-packages\sqlalchemy\util\_collections.py", line 1020, in __call__
    return self.registry[key]
KeyError: 1716

During handling of the above exception, another exception occurred:

Traceback (most recent call last):
  File "C:\Users\Amna\AppData\Local\Programs\Python\Python38\lib\site-packages\flask\app.py", line 2447, in wsgi_app
    response = self.full_dispatch_request()
  File "C:\Users\Amna\AppData\Local\Programs\Python\Python38\lib\site-packages\flask\app.py", line 1952, in full_dispatch_request
    rv = self.handle_user_exception(e)
  File "C:\Users\Amna\AppData\Local\Programs\Python\Python38\lib\site-packages\flask\app.py", line 1821, in handle_user_exception
    reraise(exc_type, exc_value, tb)
  File "C:\Users\Amna\AppData\Local\Programs\Python\Python38\lib\site-packages\flask\_compat.py", line 39, in reraise
    raise value
  File "C:\Users\Amna\AppData\Local\Programs\Python\Python38\lib\site-packages\flask\app.py", line 1950, in full_dispatch_request
    rv = self.dispatch_request()
  File "C:\Users\Amna\AppData\Local\Programs\Python\Python38\lib\site-packages\flask\app.py", line 1936, in dispatch_request
    return self.view_functions[rule.endpoint](**req.view_args)
  File "app.py", line 65, in venues
    venuesdata=Venue.query.all()
  File "C:\Users\Amna\AppData\Local\Programs\Python\Python38\lib\site-packages\flask_sqlalchemy\__init__.py", line 514, in __get__
    return type.query_class(mapper, session=self.sa.session())
  File "C:\Users\Amna\AppData\Local\Programs\Python\Python38\lib\site-packages\sqlalchemy\orm\scoping.py", line 78, in __call__
    return self.registry()
  File "C:\Users\Amna\AppData\Local\Programs\Python\Python38\lib\site-packages\sqlalchemy\util\_collections.py", line 1022, in __call__
    return self.registry.setdefault(key, self.createfunc())
  File "C:\Users\Amna\AppData\Local\Programs\Python\Python38\lib\site-packages\sqlalchemy\orm\session.py", line 3300, in __call__
    return self.class_(**local_kw)
  File "C:\Users\Amna\AppData\Local\Programs\Python\Python38\lib\site-packages\flask_sqlalchemy\__init__.py", line 137, in __init__
    track_modifications = app.config['SQLALCHEMY_TRACK_MODIFICATIONS']
KeyError: 'SQLALCHEMY_TRACK_MODIFICATIONS'
2020-10-28 13:20:52,411 ERROR: Exception on /venues [GET] [in C:\Users\Amna\AppData\Local\Programs\Python\Python38\lib\site-packages\flask\app.py:1891]
Traceback (most recent call last):
  File "C:\Users\Amna\AppData\Local\Programs\Python\Python38\lib\site-packages\sqlalchemy\util\_collections.py", line 1020, in __call__
    return self.registry[key]
KeyError: 1716

During handling of the above exception, another exception occurred:

Traceback (most recent call last):
  File "C:\Users\Amna\AppData\Local\Programs\Python\Python38\lib\site-packages\flask\app.py", line 2447, in wsgi_app
    response = self.full_dispatch_request()
  File "C:\Users\Amna\AppData\Local\Programs\Python\Python38\lib\site-packages\flask\app.py", line 1952, in full_dispatch_request
    rv = self.handle_user_exception(e)
  File "C:\Users\Amna\AppData\Local\Programs\Python\Python38\lib\site-packages\flask\app.py", line 1821, in handle_user_exception
    reraise(exc_type, exc_value, tb)
  File "C:\Users\Amna\AppData\Local\Programs\Python\Python38\lib\site-packages\flask\_compat.py", line 39, in reraise
    raise value
  File "C:\Users\Amna\AppData\Local\Programs\Python\Python38\lib\site-packages\flask\app.py", line 1950, in full_dispatch_request
    rv = self.dispatch_request()
  File "C:\Users\Amna\AppData\Local\Programs\Python\Python38\lib\site-packages\flask\app.py", line 1936, in dispatch_request
    return self.view_functions[rule.endpoint](**req.view_args)
  File "app.py", line 65, in venues
    venuesdata=Venue.query.all()
  File "C:\Users\Amna\AppData\Local\Programs\Python\Python38\lib\site-packages\flask_sqlalchemy\__init__.py", line 514, in __get__
    return type.query_class(mapper, session=self.sa.session())
  File "C:\Users\Amna\AppData\Local\Programs\Python\Python38\lib\site-packages\sqlalchemy\orm\scoping.py", line 78, in __call__
    return self.registry()
  File "C:\Users\Amna\AppData\Local\Programs\Python\Python38\lib\site-packages\sqlalchemy\util\_collections.py", line 1022, in __call__
    return self.registry.setdefault(key, self.createfunc())
  File "C:\Users\Amna\AppData\Local\Programs\Python\Python38\lib\site-packages\sqlalchemy\orm\session.py", line 3300, in __call__
    return self.class_(**local_kw)
  File "C:\Users\Amna\AppData\Local\Programs\Python\Python38\lib\site-packages\flask_sqlalchemy\__init__.py", line 137, in __init__
    track_modifications = app.config['SQLALCHEMY_TRACK_MODIFICATIONS']
KeyError: 'SQLALCHEMY_TRACK_MODIFICATIONS'
2020-10-28 13:20:53,398 ERROR: Exception on /venues [GET] [in C:\Users\Amna\AppData\Local\Programs\Python\Python38\lib\site-packages\flask\app.py:1891]
Traceback (most recent call last):
  File "C:\Users\Amna\AppData\Local\Programs\Python\Python38\lib\site-packages\sqlalchemy\util\_collections.py", line 1020, in __call__
    return self.registry[key]
KeyError: 2284

During handling of the above exception, another exception occurred:

Traceback (most recent call last):
  File "C:\Users\Amna\AppData\Local\Programs\Python\Python38\lib\site-packages\flask\app.py", line 2447, in wsgi_app
    response = self.full_dispatch_request()
  File "C:\Users\Amna\AppData\Local\Programs\Python\Python38\lib\site-packages\flask\app.py", line 1952, in full_dispatch_request
    rv = self.handle_user_exception(e)
  File "C:\Users\Amna\AppData\Local\Programs\Python\Python38\lib\site-packages\flask\app.py", line 1821, in handle_user_exception
    reraise(exc_type, exc_value, tb)
  File "C:\Users\Amna\AppData\Local\Programs\Python\Python38\lib\site-packages\flask\_compat.py", line 39, in reraise
    raise value
  File "C:\Users\Amna\AppData\Local\Programs\Python\Python38\lib\site-packages\flask\app.py", line 1950, in full_dispatch_request
    rv = self.dispatch_request()
  File "C:\Users\Amna\AppData\Local\Programs\Python\Python38\lib\site-packages\flask\app.py", line 1936, in dispatch_request
    return self.view_functions[rule.endpoint](**req.view_args)
  File "app.py", line 65, in venues
    venuesdata=Venue.query.all()
  File "C:\Users\Amna\AppData\Local\Programs\Python\Python38\lib\site-packages\flask_sqlalchemy\__init__.py", line 514, in __get__
    return type.query_class(mapper, session=self.sa.session())
  File "C:\Users\Amna\AppData\Local\Programs\Python\Python38\lib\site-packages\sqlalchemy\orm\scoping.py", line 78, in __call__
    return self.registry()
  File "C:\Users\Amna\AppData\Local\Programs\Python\Python38\lib\site-packages\sqlalchemy\util\_collections.py", line 1022, in __call__
    return self.registry.setdefault(key, self.createfunc())
  File "C:\Users\Amna\AppData\Local\Programs\Python\Python38\lib\site-packages\sqlalchemy\orm\session.py", line 3300, in __call__
    return self.class_(**local_kw)
  File "C:\Users\Amna\AppData\Local\Programs\Python\Python38\lib\site-packages\flask_sqlalchemy\__init__.py", line 137, in __init__
    track_modifications = app.config['SQLALCHEMY_TRACK_MODIFICATIONS']
KeyError: 'SQLALCHEMY_TRACK_MODIFICATIONS'
2020-10-28 13:20:53,398 ERROR: Exception on /venues [GET] [in C:\Users\Amna\AppData\Local\Programs\Python\Python38\lib\site-packages\flask\app.py:1891]
Traceback (most recent call last):
  File "C:\Users\Amna\AppData\Local\Programs\Python\Python38\lib\site-packages\sqlalchemy\util\_collections.py", line 1020, in __call__
    return self.registry[key]
KeyError: 2284

During handling of the above exception, another exception occurred:

Traceback (most recent call last):
  File "C:\Users\Amna\AppData\Local\Programs\Python\Python38\lib\site-packages\flask\app.py", line 2447, in wsgi_app
    response = self.full_dispatch_request()
  File "C:\Users\Amna\AppData\Local\Programs\Python\Python38\lib\site-packages\flask\app.py", line 1952, in full_dispatch_request
    rv = self.handle_user_exception(e)
  File "C:\Users\Amna\AppData\Local\Programs\Python\Python38\lib\site-packages\flask\app.py", line 1821, in handle_user_exception
    reraise(exc_type, exc_value, tb)
  File "C:\Users\Amna\AppData\Local\Programs\Python\Python38\lib\site-packages\flask\_compat.py", line 39, in reraise
    raise value
  File "C:\Users\Amna\AppData\Local\Programs\Python\Python38\lib\site-packages\flask\app.py", line 1950, in full_dispatch_request
    rv = self.dispatch_request()
  File "C:\Users\Amna\AppData\Local\Programs\Python\Python38\lib\site-packages\flask\app.py", line 1936, in dispatch_request
    return self.view_functions[rule.endpoint](**req.view_args)
  File "app.py", line 65, in venues
    venuesdata=Venue.query.all()
  File "C:\Users\Amna\AppData\Local\Programs\Python\Python38\lib\site-packages\flask_sqlalchemy\__init__.py", line 514, in __get__
    return type.query_class(mapper, session=self.sa.session())
  File "C:\Users\Amna\AppData\Local\Programs\Python\Python38\lib\site-packages\sqlalchemy\orm\scoping.py", line 78, in __call__
    return self.registry()
  File "C:\Users\Amna\AppData\Local\Programs\Python\Python38\lib\site-packages\sqlalchemy\util\_collections.py", line 1022, in __call__
    return self.registry.setdefault(key, self.createfunc())
  File "C:\Users\Amna\AppData\Local\Programs\Python\Python38\lib\site-packages\sqlalchemy\orm\session.py", line 3300, in __call__
    return self.class_(**local_kw)
  File "C:\Users\Amna\AppData\Local\Programs\Python\Python38\lib\site-packages\flask_sqlalchemy\__init__.py", line 137, in __init__
    track_modifications = app.config['SQLALCHEMY_TRACK_MODIFICATIONS']
KeyError: 'SQLALCHEMY_TRACK_MODIFICATIONS'
2020-10-28 13:20:54,374 ERROR: Exception on /artists [GET] [in C:\Users\Amna\AppData\Local\Programs\Python\Python38\lib\site-packages\flask\app.py:1891]
Traceback (most recent call last):
  File "C:\Users\Amna\AppData\Local\Programs\Python\Python38\lib\site-packages\sqlalchemy\util\_collections.py", line 1020, in __call__
    return self.registry[key]
KeyError: 12272

During handling of the above exception, another exception occurred:

Traceback (most recent call last):
  File "C:\Users\Amna\AppData\Local\Programs\Python\Python38\lib\site-packages\flask\app.py", line 2447, in wsgi_app
    response = self.full_dispatch_request()
  File "C:\Users\Amna\AppData\Local\Programs\Python\Python38\lib\site-packages\flask\app.py", line 1952, in full_dispatch_request
    rv = self.handle_user_exception(e)
  File "C:\Users\Amna\AppData\Local\Programs\Python\Python38\lib\site-packages\flask\app.py", line 1821, in handle_user_exception
    reraise(exc_type, exc_value, tb)
  File "C:\Users\Amna\AppData\Local\Programs\Python\Python38\lib\site-packages\flask\_compat.py", line 39, in reraise
    raise value
  File "C:\Users\Amna\AppData\Local\Programs\Python\Python38\lib\site-packages\flask\app.py", line 1950, in full_dispatch_request
    rv = self.dispatch_request()
  File "C:\Users\Amna\AppData\Local\Programs\Python\Python38\lib\site-packages\flask\app.py", line 1936, in dispatch_request
    return self.view_functions[rule.endpoint](**req.view_args)
  File "app.py", line 183, in artists
    return render_template('pages/artists.html', artists=Artist.query.all())
  File "C:\Users\Amna\AppData\Local\Programs\Python\Python38\lib\site-packages\flask_sqlalchemy\__init__.py", line 514, in __get__
    return type.query_class(mapper, session=self.sa.session())
  File "C:\Users\Amna\AppData\Local\Programs\Python\Python38\lib\site-packages\sqlalchemy\orm\scoping.py", line 78, in __call__
    return self.registry()
  File "C:\Users\Amna\AppData\Local\Programs\Python\Python38\lib\site-packages\sqlalchemy\util\_collections.py", line 1022, in __call__
    return self.registry.setdefault(key, self.createfunc())
  File "C:\Users\Amna\AppData\Local\Programs\Python\Python38\lib\site-packages\sqlalchemy\orm\session.py", line 3300, in __call__
    return self.class_(**local_kw)
  File "C:\Users\Amna\AppData\Local\Programs\Python\Python38\lib\site-packages\flask_sqlalchemy\__init__.py", line 137, in __init__
    track_modifications = app.config['SQLALCHEMY_TRACK_MODIFICATIONS']
KeyError: 'SQLALCHEMY_TRACK_MODIFICATIONS'
2020-10-28 13:20:54,374 ERROR: Exception on /artists [GET] [in C:\Users\Amna\AppData\Local\Programs\Python\Python38\lib\site-packages\flask\app.py:1891]
Traceback (most recent call last):
  File "C:\Users\Amna\AppData\Local\Programs\Python\Python38\lib\site-packages\sqlalchemy\util\_collections.py", line 1020, in __call__
    return self.registry[key]
KeyError: 12272

During handling of the above exception, another exception occurred:

Traceback (most recent call last):
  File "C:\Users\Amna\AppData\Local\Programs\Python\Python38\lib\site-packages\flask\app.py", line 2447, in wsgi_app
    response = self.full_dispatch_request()
  File "C:\Users\Amna\AppData\Local\Programs\Python\Python38\lib\site-packages\flask\app.py", line 1952, in full_dispatch_request
    rv = self.handle_user_exception(e)
  File "C:\Users\Amna\AppData\Local\Programs\Python\Python38\lib\site-packages\flask\app.py", line 1821, in handle_user_exception
    reraise(exc_type, exc_value, tb)
  File "C:\Users\Amna\AppData\Local\Programs\Python\Python38\lib\site-packages\flask\_compat.py", line 39, in reraise
    raise value
  File "C:\Users\Amna\AppData\Local\Programs\Python\Python38\lib\site-packages\flask\app.py", line 1950, in full_dispatch_request
    rv = self.dispatch_request()
  File "C:\Users\Amna\AppData\Local\Programs\Python\Python38\lib\site-packages\flask\app.py", line 1936, in dispatch_request
    return self.view_functions[rule.endpoint](**req.view_args)
  File "app.py", line 183, in artists
    return render_template('pages/artists.html', artists=Artist.query.all())
  File "C:\Users\Amna\AppData\Local\Programs\Python\Python38\lib\site-packages\flask_sqlalchemy\__init__.py", line 514, in __get__
    return type.query_class(mapper, session=self.sa.session())
  File "C:\Users\Amna\AppData\Local\Programs\Python\Python38\lib\site-packages\sqlalchemy\orm\scoping.py", line 78, in __call__
    return self.registry()
  File "C:\Users\Amna\AppData\Local\Programs\Python\Python38\lib\site-packages\sqlalchemy\util\_collections.py", line 1022, in __call__
    return self.registry.setdefault(key, self.createfunc())
  File "C:\Users\Amna\AppData\Local\Programs\Python\Python38\lib\site-packages\sqlalchemy\orm\session.py", line 3300, in __call__
    return self.class_(**local_kw)
  File "C:\Users\Amna\AppData\Local\Programs\Python\Python38\lib\site-packages\flask_sqlalchemy\__init__.py", line 137, in __init__
    track_modifications = app.config['SQLALCHEMY_TRACK_MODIFICATIONS']
KeyError: 'SQLALCHEMY_TRACK_MODIFICATIONS'
2020-10-28 13:20:55,175 ERROR: Exception on /shows [GET] [in C:\Users\Amna\AppData\Local\Programs\Python\Python38\lib\site-packages\flask\app.py:1891]
Traceback (most recent call last):
  File "C:\Users\Amna\AppData\Local\Programs\Python\Python38\lib\site-packages\sqlalchemy\util\_collections.py", line 1020, in __call__
    return self.registry[key]
KeyError: 6696

During handling of the above exception, another exception occurred:

Traceback (most recent call last):
  File "C:\Users\Amna\AppData\Local\Programs\Python\Python38\lib\site-packages\flask\app.py", line 2447, in wsgi_app
    response = self.full_dispatch_request()
  File "C:\Users\Amna\AppData\Local\Programs\Python\Python38\lib\site-packages\flask\app.py", line 1952, in full_dispatch_request
    rv = self.handle_user_exception(e)
  File "C:\Users\Amna\AppData\Local\Programs\Python\Python38\lib\site-packages\flask\app.py", line 1821, in handle_user_exception
    reraise(exc_type, exc_value, tb)
  File "C:\Users\Amna\AppData\Local\Programs\Python\Python38\lib\site-packages\flask\_compat.py", line 39, in reraise
    raise value
  File "C:\Users\Amna\AppData\Local\Programs\Python\Python38\lib\site-packages\flask\app.py", line 1950, in full_dispatch_request
    rv = self.dispatch_request()
  File "C:\Users\Amna\AppData\Local\Programs\Python\Python38\lib\site-packages\flask\app.py", line 1936, in dispatch_request
    return self.view_functions[rule.endpoint](**req.view_args)
  File "app.py", line 344, in shows
    return render_template('pages/shows.html', shows=Show.query.all())
  File "C:\Users\Amna\AppData\Local\Programs\Python\Python38\lib\site-packages\flask_sqlalchemy\__init__.py", line 514, in __get__
    return type.query_class(mapper, session=self.sa.session())
  File "C:\Users\Amna\AppData\Local\Programs\Python\Python38\lib\site-packages\sqlalchemy\orm\scoping.py", line 78, in __call__
    return self.registry()
  File "C:\Users\Amna\AppData\Local\Programs\Python\Python38\lib\site-packages\sqlalchemy\util\_collections.py", line 1022, in __call__
    return self.registry.setdefault(key, self.createfunc())
  File "C:\Users\Amna\AppData\Local\Programs\Python\Python38\lib\site-packages\sqlalchemy\orm\session.py", line 3300, in __call__
    return self.class_(**local_kw)
  File "C:\Users\Amna\AppData\Local\Programs\Python\Python38\lib\site-packages\flask_sqlalchemy\__init__.py", line 137, in __init__
    track_modifications = app.config['SQLALCHEMY_TRACK_MODIFICATIONS']
KeyError: 'SQLALCHEMY_TRACK_MODIFICATIONS'
2020-10-28 13:20:55,175 ERROR: Exception on /shows [GET] [in C:\Users\Amna\AppData\Local\Programs\Python\Python38\lib\site-packages\flask\app.py:1891]
Traceback (most recent call last):
  File "C:\Users\Amna\AppData\Local\Programs\Python\Python38\lib\site-packages\sqlalchemy\util\_collections.py", line 1020, in __call__
    return self.registry[key]
KeyError: 6696

During handling of the above exception, another exception occurred:

Traceback (most recent call last):
  File "C:\Users\Amna\AppData\Local\Programs\Python\Python38\lib\site-packages\flask\app.py", line 2447, in wsgi_app
    response = self.full_dispatch_request()
  File "C:\Users\Amna\AppData\Local\Programs\Python\Python38\lib\site-packages\flask\app.py", line 1952, in full_dispatch_request
    rv = self.handle_user_exception(e)
  File "C:\Users\Amna\AppData\Local\Programs\Python\Python38\lib\site-packages\flask\app.py", line 1821, in handle_user_exception
    reraise(exc_type, exc_value, tb)
  File "C:\Users\Amna\AppData\Local\Programs\Python\Python38\lib\site-packages\flask\_compat.py", line 39, in reraise
    raise value
  File "C:\Users\Amna\AppData\Local\Programs\Python\Python38\lib\site-packages\flask\app.py", line 1950, in full_dispatch_request
    rv = self.dispatch_request()
  File "C:\Users\Amna\AppData\Local\Programs\Python\Python38\lib\site-packages\flask\app.py", line 1936, in dispatch_request
    return self.view_functions[rule.endpoint](**req.view_args)
  File "app.py", line 344, in shows
    return render_template('pages/shows.html', shows=Show.query.all())
  File "C:\Users\Amna\AppData\Local\Programs\Python\Python38\lib\site-packages\flask_sqlalchemy\__init__.py", line 514, in __get__
    return type.query_class(mapper, session=self.sa.session())
  File "C:\Users\Amna\AppData\Local\Programs\Python\Python38\lib\site-packages\sqlalchemy\orm\scoping.py", line 78, in __call__
    return self.registry()
  File "C:\Users\Amna\AppData\Local\Programs\Python\Python38\lib\site-packages\sqlalchemy\util\_collections.py", line 1022, in __call__
    return self.registry.setdefault(key, self.createfunc())
  File "C:\Users\Amna\AppData\Local\Programs\Python\Python38\lib\site-packages\sqlalchemy\orm\session.py", line 3300, in __call__
    return self.class_(**local_kw)
  File "C:\Users\Amna\AppData\Local\Programs\Python\Python38\lib\site-packages\flask_sqlalchemy\__init__.py", line 137, in __init__
    track_modifications = app.config['SQLALCHEMY_TRACK_MODIFICATIONS']
KeyError: 'SQLALCHEMY_TRACK_MODIFICATIONS'
2020-10-28 13:20:56,445 ERROR: Exception on /venues [GET] [in C:\Users\Amna\AppData\Local\Programs\Python\Python38\lib\site-packages\flask\app.py:1891]
Traceback (most recent call last):
  File "C:\Users\Amna\AppData\Local\Programs\Python\Python38\lib\site-packages\sqlalchemy\util\_collections.py", line 1020, in __call__
    return self.registry[key]
KeyError: 2940

During handling of the above exception, another exception occurred:

Traceback (most recent call last):
  File "C:\Users\Amna\AppData\Local\Programs\Python\Python38\lib\site-packages\flask\app.py", line 2447, in wsgi_app
    response = self.full_dispatch_request()
  File "C:\Users\Amna\AppData\Local\Programs\Python\Python38\lib\site-packages\flask\app.py", line 1952, in full_dispatch_request
    rv = self.handle_user_exception(e)
  File "C:\Users\Amna\AppData\Local\Programs\Python\Python38\lib\site-packages\flask\app.py", line 1821, in handle_user_exception
    reraise(exc_type, exc_value, tb)
  File "C:\Users\Amna\AppData\Local\Programs\Python\Python38\lib\site-packages\flask\_compat.py", line 39, in reraise
    raise value
  File "C:\Users\Amna\AppData\Local\Programs\Python\Python38\lib\site-packages\flask\app.py", line 1950, in full_dispatch_request
    rv = self.dispatch_request()
  File "C:\Users\Amna\AppData\Local\Programs\Python\Python38\lib\site-packages\flask\app.py", line 1936, in dispatch_request
    return self.view_functions[rule.endpoint](**req.view_args)
  File "app.py", line 65, in venues
    venuesdata=Venue.query.all()
  File "C:\Users\Amna\AppData\Local\Programs\Python\Python38\lib\site-packages\flask_sqlalchemy\__init__.py", line 514, in __get__
    return type.query_class(mapper, session=self.sa.session())
  File "C:\Users\Amna\AppData\Local\Programs\Python\Python38\lib\site-packages\sqlalchemy\orm\scoping.py", line 78, in __call__
    return self.registry()
  File "C:\Users\Amna\AppData\Local\Programs\Python\Python38\lib\site-packages\sqlalchemy\util\_collections.py", line 1022, in __call__
    return self.registry.setdefault(key, self.createfunc())
  File "C:\Users\Amna\AppData\Local\Programs\Python\Python38\lib\site-packages\sqlalchemy\orm\session.py", line 3300, in __call__
    return self.class_(**local_kw)
  File "C:\Users\Amna\AppData\Local\Programs\Python\Python38\lib\site-packages\flask_sqlalchemy\__init__.py", line 137, in __init__
    track_modifications = app.config['SQLALCHEMY_TRACK_MODIFICATIONS']
KeyError: 'SQLALCHEMY_TRACK_MODIFICATIONS'
2020-10-28 13:20:56,445 ERROR: Exception on /venues [GET] [in C:\Users\Amna\AppData\Local\Programs\Python\Python38\lib\site-packages\flask\app.py:1891]
Traceback (most recent call last):
  File "C:\Users\Amna\AppData\Local\Programs\Python\Python38\lib\site-packages\sqlalchemy\util\_collections.py", line 1020, in __call__
    return self.registry[key]
KeyError: 2940

During handling of the above exception, another exception occurred:

Traceback (most recent call last):
  File "C:\Users\Amna\AppData\Local\Programs\Python\Python38\lib\site-packages\flask\app.py", line 2447, in wsgi_app
    response = self.full_dispatch_request()
  File "C:\Users\Amna\AppData\Local\Programs\Python\Python38\lib\site-packages\flask\app.py", line 1952, in full_dispatch_request
    rv = self.handle_user_exception(e)
  File "C:\Users\Amna\AppData\Local\Programs\Python\Python38\lib\site-packages\flask\app.py", line 1821, in handle_user_exception
    reraise(exc_type, exc_value, tb)
  File "C:\Users\Amna\AppData\Local\Programs\Python\Python38\lib\site-packages\flask\_compat.py", line 39, in reraise
    raise value
  File "C:\Users\Amna\AppData\Local\Programs\Python\Python38\lib\site-packages\flask\app.py", line 1950, in full_dispatch_request
    rv = self.dispatch_request()
  File "C:\Users\Amna\AppData\Local\Programs\Python\Python38\lib\site-packages\flask\app.py", line 1936, in dispatch_request
    return self.view_functions[rule.endpoint](**req.view_args)
  File "app.py", line 65, in venues
    venuesdata=Venue.query.all()
  File "C:\Users\Amna\AppData\Local\Programs\Python\Python38\lib\site-packages\flask_sqlalchemy\__init__.py", line 514, in __get__
    return type.query_class(mapper, session=self.sa.session())
  File "C:\Users\Amna\AppData\Local\Programs\Python\Python38\lib\site-packages\sqlalchemy\orm\scoping.py", line 78, in __call__
    return self.registry()
  File "C:\Users\Amna\AppData\Local\Programs\Python\Python38\lib\site-packages\sqlalchemy\util\_collections.py", line 1022, in __call__
    return self.registry.setdefault(key, self.createfunc())
  File "C:\Users\Amna\AppData\Local\Programs\Python\Python38\lib\site-packages\sqlalchemy\orm\session.py", line 3300, in __call__
    return self.class_(**local_kw)
  File "C:\Users\Amna\AppData\Local\Programs\Python\Python38\lib\site-packages\flask_sqlalchemy\__init__.py", line 137, in __init__
    track_modifications = app.config['SQLALCHEMY_TRACK_MODIFICATIONS']
KeyError: 'SQLALCHEMY_TRACK_MODIFICATIONS'
2020-10-28 13:20:57,438 ERROR: Exception on / [GET] [in C:\Users\Amna\AppData\Local\Programs\Python\Python38\lib\site-packages\flask\app.py:1891]
Traceback (most recent call last):
  File "C:\Users\Amna\AppData\Local\Programs\Python\Python38\lib\site-packages\sqlalchemy\util\_collections.py", line 1020, in __call__
    return self.registry[key]
KeyError: 12508

During handling of the above exception, another exception occurred:

Traceback (most recent call last):
  File "C:\Users\Amna\AppData\Local\Programs\Python\Python38\lib\site-packages\flask\app.py", line 2447, in wsgi_app
    response = self.full_dispatch_request()
  File "C:\Users\Amna\AppData\Local\Programs\Python\Python38\lib\site-packages\flask\app.py", line 1952, in full_dispatch_request
    rv = self.handle_user_exception(e)
  File "C:\Users\Amna\AppData\Local\Programs\Python\Python38\lib\site-packages\flask\app.py", line 1821, in handle_user_exception
    reraise(exc_type, exc_value, tb)
  File "C:\Users\Amna\AppData\Local\Programs\Python\Python38\lib\site-packages\flask\_compat.py", line 39, in reraise
    raise value
  File "C:\Users\Amna\AppData\Local\Programs\Python\Python38\lib\site-packages\flask\app.py", line 1950, in full_dispatch_request
    rv = self.dispatch_request()
  File "C:\Users\Amna\AppData\Local\Programs\Python\Python38\lib\site-packages\flask\app.py", line 1936, in dispatch_request
    return self.view_functions[rule.endpoint](**req.view_args)
  File "app.py", line 56, in index
    latestvenues=db.session.query(Venue).order_by(desc(Venue.id)).limit(10).all(),
  File "C:\Users\Amna\AppData\Local\Programs\Python\Python38\lib\site-packages\sqlalchemy\orm\scoping.py", line 163, in do
    return getattr(self.registry(), name)(*args, **kwargs)
  File "C:\Users\Amna\AppData\Local\Programs\Python\Python38\lib\site-packages\sqlalchemy\util\_collections.py", line 1022, in __call__
    return self.registry.setdefault(key, self.createfunc())
  File "C:\Users\Amna\AppData\Local\Programs\Python\Python38\lib\site-packages\sqlalchemy\orm\session.py", line 3300, in __call__
    return self.class_(**local_kw)
  File "C:\Users\Amna\AppData\Local\Programs\Python\Python38\lib\site-packages\flask_sqlalchemy\__init__.py", line 137, in __init__
    track_modifications = app.config['SQLALCHEMY_TRACK_MODIFICATIONS']
KeyError: 'SQLALCHEMY_TRACK_MODIFICATIONS'
2020-10-28 13:20:57,438 ERROR: Exception on / [GET] [in C:\Users\Amna\AppData\Local\Programs\Python\Python38\lib\site-packages\flask\app.py:1891]
Traceback (most recent call last):
  File "C:\Users\Amna\AppData\Local\Programs\Python\Python38\lib\site-packages\sqlalchemy\util\_collections.py", line 1020, in __call__
    return self.registry[key]
KeyError: 12508

During handling of the above exception, another exception occurred:

Traceback (most recent call last):
  File "C:\Users\Amna\AppData\Local\Programs\Python\Python38\lib\site-packages\flask\app.py", line 2447, in wsgi_app
    response = self.full_dispatch_request()
  File "C:\Users\Amna\AppData\Local\Programs\Python\Python38\lib\site-packages\flask\app.py", line 1952, in full_dispatch_request
    rv = self.handle_user_exception(e)
  File "C:\Users\Amna\AppData\Local\Programs\Python\Python38\lib\site-packages\flask\app.py", line 1821, in handle_user_exception
    reraise(exc_type, exc_value, tb)
  File "C:\Users\Amna\AppData\Local\Programs\Python\Python38\lib\site-packages\flask\_compat.py", line 39, in reraise
    raise value
  File "C:\Users\Amna\AppData\Local\Programs\Python\Python38\lib\site-packages\flask\app.py", line 1950, in full_dispatch_request
    rv = self.dispatch_request()
  File "C:\Users\Amna\AppData\Local\Programs\Python\Python38\lib\site-packages\flask\app.py", line 1936, in dispatch_request
    return self.view_functions[rule.endpoint](**req.view_args)
  File "app.py", line 56, in index
    latestvenues=db.session.query(Venue).order_by(desc(Venue.id)).limit(10).all(),
  File "C:\Users\Amna\AppData\Local\Programs\Python\Python38\lib\site-packages\sqlalchemy\orm\scoping.py", line 163, in do
    return getattr(self.registry(), name)(*args, **kwargs)
  File "C:\Users\Amna\AppData\Local\Programs\Python\Python38\lib\site-packages\sqlalchemy\util\_collections.py", line 1022, in __call__
    return self.registry.setdefault(key, self.createfunc())
  File "C:\Users\Amna\AppData\Local\Programs\Python\Python38\lib\site-packages\sqlalchemy\orm\session.py", line 3300, in __call__
    return self.class_(**local_kw)
  File "C:\Users\Amna\AppData\Local\Programs\Python\Python38\lib\site-packages\flask_sqlalchemy\__init__.py", line 137, in __init__
    track_modifications = app.config['SQLALCHEMY_TRACK_MODIFICATIONS']
KeyError: 'SQLALCHEMY_TRACK_MODIFICATIONS'
2020-10-28 13:21:18,849 ERROR: Exception on / [GET] [in C:\Users\Amna\AppData\Local\Programs\Python\Python38\lib\site-packages\flask\app.py:1891]
Traceback (most recent call last):
  File "C:\Users\Amna\AppData\Local\Programs\Python\Python38\lib\site-packages\sqlalchemy\util\_collections.py", line 1020, in __call__
    return self.registry[key]
KeyError: 12864

During handling of the above exception, another exception occurred:

Traceback (most recent call last):
  File "C:\Users\Amna\AppData\Local\Programs\Python\Python38\lib\site-packages\flask\app.py", line 2447, in wsgi_app
    response = self.full_dispatch_request()
  File "C:\Users\Amna\AppData\Local\Programs\Python\Python38\lib\site-packages\flask\app.py", line 1952, in full_dispatch_request
    rv = self.handle_user_exception(e)
  File "C:\Users\Amna\AppData\Local\Programs\Python\Python38\lib\site-packages\flask\app.py", line 1821, in handle_user_exception
    reraise(exc_type, exc_value, tb)
  File "C:\Users\Amna\AppData\Local\Programs\Python\Python38\lib\site-packages\flask\_compat.py", line 39, in reraise
    raise value
  File "C:\Users\Amna\AppData\Local\Programs\Python\Python38\lib\site-packages\flask\app.py", line 1950, in full_dispatch_request
    rv = self.dispatch_request()
  File "C:\Users\Amna\AppData\Local\Programs\Python\Python38\lib\site-packages\flask\app.py", line 1936, in dispatch_request
    return self.view_functions[rule.endpoint](**req.view_args)
  File "app.py", line 56, in index
    venue['address']=self.address
  File "C:\Users\Amna\AppData\Local\Programs\Python\Python38\lib\site-packages\sqlalchemy\orm\scoping.py", line 163, in do
    return getattr(self.registry(), name)(*args, **kwargs)
  File "C:\Users\Amna\AppData\Local\Programs\Python\Python38\lib\site-packages\sqlalchemy\util\_collections.py", line 1022, in __call__
    return self.registry.setdefault(key, self.createfunc())
  File "C:\Users\Amna\AppData\Local\Programs\Python\Python38\lib\site-packages\sqlalchemy\orm\session.py", line 3300, in __call__
    return self.class_(**local_kw)
  File "C:\Users\Amna\AppData\Local\Programs\Python\Python38\lib\site-packages\flask_sqlalchemy\__init__.py", line 137, in __init__
    track_modifications = app.config['SQLALCHEMY_TRACK_MODIFICATIONS']
KeyError: 'SQLALCHEMY_TRACK_MODIFICATIONS'
2020-10-28 13:21:18,849 ERROR: Exception on / [GET] [in C:\Users\Amna\AppData\Local\Programs\Python\Python38\lib\site-packages\flask\app.py:1891]
Traceback (most recent call last):
  File "C:\Users\Amna\AppData\Local\Programs\Python\Python38\lib\site-packages\sqlalchemy\util\_collections.py", line 1020, in __call__
    return self.registry[key]
KeyError: 12864

During handling of the above exception, another exception occurred:

Traceback (most recent call last):
  File "C:\Users\Amna\AppData\Local\Programs\Python\Python38\lib\site-packages\flask\app.py", line 2447, in wsgi_app
    response = self.full_dispatch_request()
  File "C:\Users\Amna\AppData\Local\Programs\Python\Python38\lib\site-packages\flask\app.py", line 1952, in full_dispatch_request
    rv = self.handle_user_exception(e)
  File "C:\Users\Amna\AppData\Local\Programs\Python\Python38\lib\site-packages\flask\app.py", line 1821, in handle_user_exception
    reraise(exc_type, exc_value, tb)
  File "C:\Users\Amna\AppData\Local\Programs\Python\Python38\lib\site-packages\flask\_compat.py", line 39, in reraise
    raise value
  File "C:\Users\Amna\AppData\Local\Programs\Python\Python38\lib\site-packages\flask\app.py", line 1950, in full_dispatch_request
    rv = self.dispatch_request()
  File "C:\Users\Amna\AppData\Local\Programs\Python\Python38\lib\site-packages\flask\app.py", line 1936, in dispatch_request
    return self.view_functions[rule.endpoint](**req.view_args)
  File "app.py", line 56, in index
    venue['address']=self.address
  File "C:\Users\Amna\AppData\Local\Programs\Python\Python38\lib\site-packages\sqlalchemy\orm\scoping.py", line 163, in do
    return getattr(self.registry(), name)(*args, **kwargs)
  File "C:\Users\Amna\AppData\Local\Programs\Python\Python38\lib\site-packages\sqlalchemy\util\_collections.py", line 1022, in __call__
    return self.registry.setdefault(key, self.createfunc())
  File "C:\Users\Amna\AppData\Local\Programs\Python\Python38\lib\site-packages\sqlalchemy\orm\session.py", line 3300, in __call__
    return self.class_(**local_kw)
  File "C:\Users\Amna\AppData\Local\Programs\Python\Python38\lib\site-packages\flask_sqlalchemy\__init__.py", line 137, in __init__
    track_modifications = app.config['SQLALCHEMY_TRACK_MODIFICATIONS']
KeyError: 'SQLALCHEMY_TRACK_MODIFICATIONS'
2020-10-28 13:21:20,273 ERROR: Exception on /venues [GET] [in C:\Users\Amna\AppData\Local\Programs\Python\Python38\lib\site-packages\flask\app.py:1891]
Traceback (most recent call last):
  File "C:\Users\Amna\AppData\Local\Programs\Python\Python38\lib\site-packages\sqlalchemy\util\_collections.py", line 1020, in __call__
    return self.registry[key]
KeyError: 2964

During handling of the above exception, another exception occurred:

Traceback (most recent call last):
  File "C:\Users\Amna\AppData\Local\Programs\Python\Python38\lib\site-packages\flask\app.py", line 2447, in wsgi_app
    response = self.full_dispatch_request()
  File "C:\Users\Amna\AppData\Local\Programs\Python\Python38\lib\site-packages\flask\app.py", line 1952, in full_dispatch_request
    rv = self.handle_user_exception(e)
  File "C:\Users\Amna\AppData\Local\Programs\Python\Python38\lib\site-packages\flask\app.py", line 1821, in handle_user_exception
    reraise(exc_type, exc_value, tb)
  File "C:\Users\Amna\AppData\Local\Programs\Python\Python38\lib\site-packages\flask\_compat.py", line 39, in reraise
    raise value
  File "C:\Users\Amna\AppData\Local\Programs\Python\Python38\lib\site-packages\flask\app.py", line 1950, in full_dispatch_request
    rv = self.dispatch_request()
  File "C:\Users\Amna\AppData\Local\Programs\Python\Python38\lib\site-packages\flask\app.py", line 1936, in dispatch_request
    return self.view_functions[rule.endpoint](**req.view_args)
  File "app.py", line 65, in venues
  File "C:\Users\Amna\AppData\Local\Programs\Python\Python38\lib\site-packages\flask_sqlalchemy\__init__.py", line 514, in __get__
    return type.query_class(mapper, session=self.sa.session())
  File "C:\Users\Amna\AppData\Local\Programs\Python\Python38\lib\site-packages\sqlalchemy\orm\scoping.py", line 78, in __call__
    return self.registry()
  File "C:\Users\Amna\AppData\Local\Programs\Python\Python38\lib\site-packages\sqlalchemy\util\_collections.py", line 1022, in __call__
    return self.registry.setdefault(key, self.createfunc())
  File "C:\Users\Amna\AppData\Local\Programs\Python\Python38\lib\site-packages\sqlalchemy\orm\session.py", line 3300, in __call__
    return self.class_(**local_kw)
  File "C:\Users\Amna\AppData\Local\Programs\Python\Python38\lib\site-packages\flask_sqlalchemy\__init__.py", line 137, in __init__
    track_modifications = app.config['SQLALCHEMY_TRACK_MODIFICATIONS']
KeyError: 'SQLALCHEMY_TRACK_MODIFICATIONS'
2020-10-28 13:21:20,273 ERROR: Exception on /venues [GET] [in C:\Users\Amna\AppData\Local\Programs\Python\Python38\lib\site-packages\flask\app.py:1891]
Traceback (most recent call last):
  File "C:\Users\Amna\AppData\Local\Programs\Python\Python38\lib\site-packages\sqlalchemy\util\_collections.py", line 1020, in __call__
    return self.registry[key]
KeyError: 2964

During handling of the above exception, another exception occurred:

Traceback (most recent call last):
  File "C:\Users\Amna\AppData\Local\Programs\Python\Python38\lib\site-packages\flask\app.py", line 2447, in wsgi_app
    response = self.full_dispatch_request()
  File "C:\Users\Amna\AppData\Local\Programs\Python\Python38\lib\site-packages\flask\app.py", line 1952, in full_dispatch_request
    rv = self.handle_user_exception(e)
  File "C:\Users\Amna\AppData\Local\Programs\Python\Python38\lib\site-packages\flask\app.py", line 1821, in handle_user_exception
    reraise(exc_type, exc_value, tb)
  File "C:\Users\Amna\AppData\Local\Programs\Python\Python38\lib\site-packages\flask\_compat.py", line 39, in reraise
    raise value
  File "C:\Users\Amna\AppData\Local\Programs\Python\Python38\lib\site-packages\flask\app.py", line 1950, in full_dispatch_request
    rv = self.dispatch_request()
  File "C:\Users\Amna\AppData\Local\Programs\Python\Python38\lib\site-packages\flask\app.py", line 1936, in dispatch_request
    return self.view_functions[rule.endpoint](**req.view_args)
  File "app.py", line 65, in venues
  File "C:\Users\Amna\AppData\Local\Programs\Python\Python38\lib\site-packages\flask_sqlalchemy\__init__.py", line 514, in __get__
    return type.query_class(mapper, session=self.sa.session())
  File "C:\Users\Amna\AppData\Local\Programs\Python\Python38\lib\site-packages\sqlalchemy\orm\scoping.py", line 78, in __call__
    return self.registry()
  File "C:\Users\Amna\AppData\Local\Programs\Python\Python38\lib\site-packages\sqlalchemy\util\_collections.py", line 1022, in __call__
    return self.registry.setdefault(key, self.createfunc())
  File "C:\Users\Amna\AppData\Local\Programs\Python\Python38\lib\site-packages\sqlalchemy\orm\session.py", line 3300, in __call__
    return self.class_(**local_kw)
  File "C:\Users\Amna\AppData\Local\Programs\Python\Python38\lib\site-packages\flask_sqlalchemy\__init__.py", line 137, in __init__
    track_modifications = app.config['SQLALCHEMY_TRACK_MODIFICATIONS']
KeyError: 'SQLALCHEMY_TRACK_MODIFICATIONS'
2020-10-28 13:27:07,296 INFO: errors [in C:\Users\Amna\class-demos\fyyur\starter_code\app.py:395]
2020-10-28 13:27:07,329 INFO: errors [in app.py:395]
2020-10-28 13:27:07,329 INFO: errors [in app.py:395]
2020-10-28 13:27:25,359 ERROR: Exception on /venues/4 [GET] [in C:\Users\Amna\AppData\Local\Programs\Python\Python38\lib\site-packages\flask\app.py:1891]
Traceback (most recent call last):
  File "C:\Users\Amna\AppData\Local\Programs\Python\Python38\lib\site-packages\sqlalchemy\util\_collections.py", line 1020, in __call__
    return self.registry[key]
KeyError: 8692

During handling of the above exception, another exception occurred:

Traceback (most recent call last):
  File "C:\Users\Amna\AppData\Local\Programs\Python\Python38\lib\site-packages\flask\app.py", line 2447, in wsgi_app
    response = self.full_dispatch_request()
  File "C:\Users\Amna\AppData\Local\Programs\Python\Python38\lib\site-packages\flask\app.py", line 1952, in full_dispatch_request
    rv = self.handle_user_exception(e)
  File "C:\Users\Amna\AppData\Local\Programs\Python\Python38\lib\site-packages\flask\app.py", line 1821, in handle_user_exception
    reraise(exc_type, exc_value, tb)
  File "C:\Users\Amna\AppData\Local\Programs\Python\Python38\lib\site-packages\flask\_compat.py", line 39, in reraise
    raise value
  File "C:\Users\Amna\AppData\Local\Programs\Python\Python38\lib\site-packages\flask\app.py", line 1950, in full_dispatch_request
    rv = self.dispatch_request()
  File "C:\Users\Amna\AppData\Local\Programs\Python\Python38\lib\site-packages\flask\app.py", line 1936, in dispatch_request
    return self.view_functions[rule.endpoint](**req.view_args)
  File "app.py", line 115, in show_venue
    venue=Venue.query.get(venue_id)
  File "C:\Users\Amna\AppData\Local\Programs\Python\Python38\lib\site-packages\flask_sqlalchemy\__init__.py", line 514, in __get__
    return type.query_class(mapper, session=self.sa.session())
  File "C:\Users\Amna\AppData\Local\Programs\Python\Python38\lib\site-packages\sqlalchemy\orm\scoping.py", line 78, in __call__
    return self.registry()
  File "C:\Users\Amna\AppData\Local\Programs\Python\Python38\lib\site-packages\sqlalchemy\util\_collections.py", line 1022, in __call__
    return self.registry.setdefault(key, self.createfunc())
  File "C:\Users\Amna\AppData\Local\Programs\Python\Python38\lib\site-packages\sqlalchemy\orm\session.py", line 3300, in __call__
    return self.class_(**local_kw)
  File "C:\Users\Amna\AppData\Local\Programs\Python\Python38\lib\site-packages\flask_sqlalchemy\__init__.py", line 137, in __init__
    track_modifications = app.config['SQLALCHEMY_TRACK_MODIFICATIONS']
KeyError: 'SQLALCHEMY_TRACK_MODIFICATIONS'
2020-10-28 13:27:25,359 ERROR: Exception on /venues/4 [GET] [in C:\Users\Amna\AppData\Local\Programs\Python\Python38\lib\site-packages\flask\app.py:1891]
Traceback (most recent call last):
  File "C:\Users\Amna\AppData\Local\Programs\Python\Python38\lib\site-packages\sqlalchemy\util\_collections.py", line 1020, in __call__
    return self.registry[key]
KeyError: 8692

During handling of the above exception, another exception occurred:

Traceback (most recent call last):
  File "C:\Users\Amna\AppData\Local\Programs\Python\Python38\lib\site-packages\flask\app.py", line 2447, in wsgi_app
    response = self.full_dispatch_request()
  File "C:\Users\Amna\AppData\Local\Programs\Python\Python38\lib\site-packages\flask\app.py", line 1952, in full_dispatch_request
    rv = self.handle_user_exception(e)
  File "C:\Users\Amna\AppData\Local\Programs\Python\Python38\lib\site-packages\flask\app.py", line 1821, in handle_user_exception
    reraise(exc_type, exc_value, tb)
  File "C:\Users\Amna\AppData\Local\Programs\Python\Python38\lib\site-packages\flask\_compat.py", line 39, in reraise
    raise value
  File "C:\Users\Amna\AppData\Local\Programs\Python\Python38\lib\site-packages\flask\app.py", line 1950, in full_dispatch_request
    rv = self.dispatch_request()
  File "C:\Users\Amna\AppData\Local\Programs\Python\Python38\lib\site-packages\flask\app.py", line 1936, in dispatch_request
    return self.view_functions[rule.endpoint](**req.view_args)
  File "app.py", line 115, in show_venue
    venue=Venue.query.get(venue_id)
  File "C:\Users\Amna\AppData\Local\Programs\Python\Python38\lib\site-packages\flask_sqlalchemy\__init__.py", line 514, in __get__
    return type.query_class(mapper, session=self.sa.session())
  File "C:\Users\Amna\AppData\Local\Programs\Python\Python38\lib\site-packages\sqlalchemy\orm\scoping.py", line 78, in __call__
    return self.registry()
  File "C:\Users\Amna\AppData\Local\Programs\Python\Python38\lib\site-packages\sqlalchemy\util\_collections.py", line 1022, in __call__
    return self.registry.setdefault(key, self.createfunc())
  File "C:\Users\Amna\AppData\Local\Programs\Python\Python38\lib\site-packages\sqlalchemy\orm\session.py", line 3300, in __call__
    return self.class_(**local_kw)
  File "C:\Users\Amna\AppData\Local\Programs\Python\Python38\lib\site-packages\flask_sqlalchemy\__init__.py", line 137, in __init__
    track_modifications = app.config['SQLALCHEMY_TRACK_MODIFICATIONS']
KeyError: 'SQLALCHEMY_TRACK_MODIFICATIONS'
2020-10-28 13:27:26,998 ERROR: Exception on /venues [GET] [in C:\Users\Amna\AppData\Local\Programs\Python\Python38\lib\site-packages\flask\app.py:1891]
Traceback (most recent call last):
  File "C:\Users\Amna\AppData\Local\Programs\Python\Python38\lib\site-packages\sqlalchemy\util\_collections.py", line 1020, in __call__
    return self.registry[key]
KeyError: 8452

During handling of the above exception, another exception occurred:

Traceback (most recent call last):
  File "C:\Users\Amna\AppData\Local\Programs\Python\Python38\lib\site-packages\flask\app.py", line 2447, in wsgi_app
    response = self.full_dispatch_request()
  File "C:\Users\Amna\AppData\Local\Programs\Python\Python38\lib\site-packages\flask\app.py", line 1952, in full_dispatch_request
    rv = self.handle_user_exception(e)
  File "C:\Users\Amna\AppData\Local\Programs\Python\Python38\lib\site-packages\flask\app.py", line 1821, in handle_user_exception
    reraise(exc_type, exc_value, tb)
  File "C:\Users\Amna\AppData\Local\Programs\Python\Python38\lib\site-packages\flask\_compat.py", line 39, in reraise
    raise value
  File "C:\Users\Amna\AppData\Local\Programs\Python\Python38\lib\site-packages\flask\app.py", line 1950, in full_dispatch_request
    rv = self.dispatch_request()
  File "C:\Users\Amna\AppData\Local\Programs\Python\Python38\lib\site-packages\flask\app.py", line 1936, in dispatch_request
    return self.view_functions[rule.endpoint](**req.view_args)
  File "app.py", line 69, in venues
    venuesdata=Venue.query.all()
  File "C:\Users\Amna\AppData\Local\Programs\Python\Python38\lib\site-packages\flask_sqlalchemy\__init__.py", line 514, in __get__
    return type.query_class(mapper, session=self.sa.session())
  File "C:\Users\Amna\AppData\Local\Programs\Python\Python38\lib\site-packages\sqlalchemy\orm\scoping.py", line 78, in __call__
    return self.registry()
  File "C:\Users\Amna\AppData\Local\Programs\Python\Python38\lib\site-packages\sqlalchemy\util\_collections.py", line 1022, in __call__
    return self.registry.setdefault(key, self.createfunc())
  File "C:\Users\Amna\AppData\Local\Programs\Python\Python38\lib\site-packages\sqlalchemy\orm\session.py", line 3300, in __call__
    return self.class_(**local_kw)
  File "C:\Users\Amna\AppData\Local\Programs\Python\Python38\lib\site-packages\flask_sqlalchemy\__init__.py", line 137, in __init__
    track_modifications = app.config['SQLALCHEMY_TRACK_MODIFICATIONS']
KeyError: 'SQLALCHEMY_TRACK_MODIFICATIONS'
2020-10-28 13:27:26,998 ERROR: Exception on /venues [GET] [in C:\Users\Amna\AppData\Local\Programs\Python\Python38\lib\site-packages\flask\app.py:1891]
Traceback (most recent call last):
  File "C:\Users\Amna\AppData\Local\Programs\Python\Python38\lib\site-packages\sqlalchemy\util\_collections.py", line 1020, in __call__
    return self.registry[key]
KeyError: 8452

During handling of the above exception, another exception occurred:

Traceback (most recent call last):
  File "C:\Users\Amna\AppData\Local\Programs\Python\Python38\lib\site-packages\flask\app.py", line 2447, in wsgi_app
    response = self.full_dispatch_request()
  File "C:\Users\Amna\AppData\Local\Programs\Python\Python38\lib\site-packages\flask\app.py", line 1952, in full_dispatch_request
    rv = self.handle_user_exception(e)
  File "C:\Users\Amna\AppData\Local\Programs\Python\Python38\lib\site-packages\flask\app.py", line 1821, in handle_user_exception
    reraise(exc_type, exc_value, tb)
  File "C:\Users\Amna\AppData\Local\Programs\Python\Python38\lib\site-packages\flask\_compat.py", line 39, in reraise
    raise value
  File "C:\Users\Amna\AppData\Local\Programs\Python\Python38\lib\site-packages\flask\app.py", line 1950, in full_dispatch_request
    rv = self.dispatch_request()
  File "C:\Users\Amna\AppData\Local\Programs\Python\Python38\lib\site-packages\flask\app.py", line 1936, in dispatch_request
    return self.view_functions[rule.endpoint](**req.view_args)
  File "app.py", line 69, in venues
    venuesdata=Venue.query.all()
  File "C:\Users\Amna\AppData\Local\Programs\Python\Python38\lib\site-packages\flask_sqlalchemy\__init__.py", line 514, in __get__
    return type.query_class(mapper, session=self.sa.session())
  File "C:\Users\Amna\AppData\Local\Programs\Python\Python38\lib\site-packages\sqlalchemy\orm\scoping.py", line 78, in __call__
    return self.registry()
  File "C:\Users\Amna\AppData\Local\Programs\Python\Python38\lib\site-packages\sqlalchemy\util\_collections.py", line 1022, in __call__
    return self.registry.setdefault(key, self.createfunc())
  File "C:\Users\Amna\AppData\Local\Programs\Python\Python38\lib\site-packages\sqlalchemy\orm\session.py", line 3300, in __call__
    return self.class_(**local_kw)
  File "C:\Users\Amna\AppData\Local\Programs\Python\Python38\lib\site-packages\flask_sqlalchemy\__init__.py", line 137, in __init__
    track_modifications = app.config['SQLALCHEMY_TRACK_MODIFICATIONS']
KeyError: 'SQLALCHEMY_TRACK_MODIFICATIONS'
2020-10-28 13:27:27,894 ERROR: Exception on /artists [GET] [in C:\Users\Amna\AppData\Local\Programs\Python\Python38\lib\site-packages\flask\app.py:1891]
Traceback (most recent call last):
  File "C:\Users\Amna\AppData\Local\Programs\Python\Python38\lib\site-packages\sqlalchemy\util\_collections.py", line 1020, in __call__
    return self.registry[key]
KeyError: 4980

During handling of the above exception, another exception occurred:

Traceback (most recent call last):
  File "C:\Users\Amna\AppData\Local\Programs\Python\Python38\lib\site-packages\flask\app.py", line 2447, in wsgi_app
    response = self.full_dispatch_request()
  File "C:\Users\Amna\AppData\Local\Programs\Python\Python38\lib\site-packages\flask\app.py", line 1952, in full_dispatch_request
    rv = self.handle_user_exception(e)
  File "C:\Users\Amna\AppData\Local\Programs\Python\Python38\lib\site-packages\flask\app.py", line 1821, in handle_user_exception
    reraise(exc_type, exc_value, tb)
  File "C:\Users\Amna\AppData\Local\Programs\Python\Python38\lib\site-packages\flask\_compat.py", line 39, in reraise
    raise value
  File "C:\Users\Amna\AppData\Local\Programs\Python\Python38\lib\site-packages\flask\app.py", line 1950, in full_dispatch_request
    rv = self.dispatch_request()
  File "C:\Users\Amna\AppData\Local\Programs\Python\Python38\lib\site-packages\flask\app.py", line 1936, in dispatch_request
    return self.view_functions[rule.endpoint](**req.view_args)
  File "app.py", line 187, in artists
    return render_template('pages/artists.html', artists=Artist.query.all())
  File "C:\Users\Amna\AppData\Local\Programs\Python\Python38\lib\site-packages\flask_sqlalchemy\__init__.py", line 514, in __get__
    return type.query_class(mapper, session=self.sa.session())
  File "C:\Users\Amna\AppData\Local\Programs\Python\Python38\lib\site-packages\sqlalchemy\orm\scoping.py", line 78, in __call__
    return self.registry()
  File "C:\Users\Amna\AppData\Local\Programs\Python\Python38\lib\site-packages\sqlalchemy\util\_collections.py", line 1022, in __call__
    return self.registry.setdefault(key, self.createfunc())
  File "C:\Users\Amna\AppData\Local\Programs\Python\Python38\lib\site-packages\sqlalchemy\orm\session.py", line 3300, in __call__
    return self.class_(**local_kw)
  File "C:\Users\Amna\AppData\Local\Programs\Python\Python38\lib\site-packages\flask_sqlalchemy\__init__.py", line 137, in __init__
    track_modifications = app.config['SQLALCHEMY_TRACK_MODIFICATIONS']
KeyError: 'SQLALCHEMY_TRACK_MODIFICATIONS'
2020-10-28 13:27:27,894 ERROR: Exception on /artists [GET] [in C:\Users\Amna\AppData\Local\Programs\Python\Python38\lib\site-packages\flask\app.py:1891]
Traceback (most recent call last):
  File "C:\Users\Amna\AppData\Local\Programs\Python\Python38\lib\site-packages\sqlalchemy\util\_collections.py", line 1020, in __call__
    return self.registry[key]
KeyError: 4980

During handling of the above exception, another exception occurred:

Traceback (most recent call last):
  File "C:\Users\Amna\AppData\Local\Programs\Python\Python38\lib\site-packages\flask\app.py", line 2447, in wsgi_app
    response = self.full_dispatch_request()
  File "C:\Users\Amna\AppData\Local\Programs\Python\Python38\lib\site-packages\flask\app.py", line 1952, in full_dispatch_request
    rv = self.handle_user_exception(e)
  File "C:\Users\Amna\AppData\Local\Programs\Python\Python38\lib\site-packages\flask\app.py", line 1821, in handle_user_exception
    reraise(exc_type, exc_value, tb)
  File "C:\Users\Amna\AppData\Local\Programs\Python\Python38\lib\site-packages\flask\_compat.py", line 39, in reraise
    raise value
  File "C:\Users\Amna\AppData\Local\Programs\Python\Python38\lib\site-packages\flask\app.py", line 1950, in full_dispatch_request
    rv = self.dispatch_request()
  File "C:\Users\Amna\AppData\Local\Programs\Python\Python38\lib\site-packages\flask\app.py", line 1936, in dispatch_request
    return self.view_functions[rule.endpoint](**req.view_args)
  File "app.py", line 187, in artists
    return render_template('pages/artists.html', artists=Artist.query.all())
  File "C:\Users\Amna\AppData\Local\Programs\Python\Python38\lib\site-packages\flask_sqlalchemy\__init__.py", line 514, in __get__
    return type.query_class(mapper, session=self.sa.session())
  File "C:\Users\Amna\AppData\Local\Programs\Python\Python38\lib\site-packages\sqlalchemy\orm\scoping.py", line 78, in __call__
    return self.registry()
  File "C:\Users\Amna\AppData\Local\Programs\Python\Python38\lib\site-packages\sqlalchemy\util\_collections.py", line 1022, in __call__
    return self.registry.setdefault(key, self.createfunc())
  File "C:\Users\Amna\AppData\Local\Programs\Python\Python38\lib\site-packages\sqlalchemy\orm\session.py", line 3300, in __call__
    return self.class_(**local_kw)
  File "C:\Users\Amna\AppData\Local\Programs\Python\Python38\lib\site-packages\flask_sqlalchemy\__init__.py", line 137, in __init__
    track_modifications = app.config['SQLALCHEMY_TRACK_MODIFICATIONS']
KeyError: 'SQLALCHEMY_TRACK_MODIFICATIONS'
2020-10-28 13:27:28,749 ERROR: Exception on / [GET] [in C:\Users\Amna\AppData\Local\Programs\Python\Python38\lib\site-packages\flask\app.py:1891]
Traceback (most recent call last):
  File "C:\Users\Amna\AppData\Local\Programs\Python\Python38\lib\site-packages\sqlalchemy\util\_collections.py", line 1020, in __call__
    return self.registry[key]
KeyError: 6696

During handling of the above exception, another exception occurred:

Traceback (most recent call last):
  File "C:\Users\Amna\AppData\Local\Programs\Python\Python38\lib\site-packages\flask\app.py", line 2447, in wsgi_app
    response = self.full_dispatch_request()
  File "C:\Users\Amna\AppData\Local\Programs\Python\Python38\lib\site-packages\flask\app.py", line 1952, in full_dispatch_request
    rv = self.handle_user_exception(e)
  File "C:\Users\Amna\AppData\Local\Programs\Python\Python38\lib\site-packages\flask\app.py", line 1821, in handle_user_exception
    reraise(exc_type, exc_value, tb)
  File "C:\Users\Amna\AppData\Local\Programs\Python\Python38\lib\site-packages\flask\_compat.py", line 39, in reraise
    raise value
  File "C:\Users\Amna\AppData\Local\Programs\Python\Python38\lib\site-packages\flask\app.py", line 1950, in full_dispatch_request
    rv = self.dispatch_request()
  File "C:\Users\Amna\AppData\Local\Programs\Python\Python38\lib\site-packages\flask\app.py", line 1936, in dispatch_request
    return self.view_functions[rule.endpoint](**req.view_args)
  File "app.py", line 60, in index
    latestvenues=db.session.query(Venue).order_by(desc(Venue.id)).limit(10).all(),
  File "C:\Users\Amna\AppData\Local\Programs\Python\Python38\lib\site-packages\sqlalchemy\orm\scoping.py", line 163, in do
    return getattr(self.registry(), name)(*args, **kwargs)
  File "C:\Users\Amna\AppData\Local\Programs\Python\Python38\lib\site-packages\sqlalchemy\util\_collections.py", line 1022, in __call__
    return self.registry.setdefault(key, self.createfunc())
  File "C:\Users\Amna\AppData\Local\Programs\Python\Python38\lib\site-packages\sqlalchemy\orm\session.py", line 3300, in __call__
    return self.class_(**local_kw)
  File "C:\Users\Amna\AppData\Local\Programs\Python\Python38\lib\site-packages\flask_sqlalchemy\__init__.py", line 137, in __init__
    track_modifications = app.config['SQLALCHEMY_TRACK_MODIFICATIONS']
KeyError: 'SQLALCHEMY_TRACK_MODIFICATIONS'
2020-10-28 13:27:28,749 ERROR: Exception on / [GET] [in C:\Users\Amna\AppData\Local\Programs\Python\Python38\lib\site-packages\flask\app.py:1891]
Traceback (most recent call last):
  File "C:\Users\Amna\AppData\Local\Programs\Python\Python38\lib\site-packages\sqlalchemy\util\_collections.py", line 1020, in __call__
    return self.registry[key]
KeyError: 6696

During handling of the above exception, another exception occurred:

Traceback (most recent call last):
  File "C:\Users\Amna\AppData\Local\Programs\Python\Python38\lib\site-packages\flask\app.py", line 2447, in wsgi_app
    response = self.full_dispatch_request()
  File "C:\Users\Amna\AppData\Local\Programs\Python\Python38\lib\site-packages\flask\app.py", line 1952, in full_dispatch_request
    rv = self.handle_user_exception(e)
  File "C:\Users\Amna\AppData\Local\Programs\Python\Python38\lib\site-packages\flask\app.py", line 1821, in handle_user_exception
    reraise(exc_type, exc_value, tb)
  File "C:\Users\Amna\AppData\Local\Programs\Python\Python38\lib\site-packages\flask\_compat.py", line 39, in reraise
    raise value
  File "C:\Users\Amna\AppData\Local\Programs\Python\Python38\lib\site-packages\flask\app.py", line 1950, in full_dispatch_request
    rv = self.dispatch_request()
  File "C:\Users\Amna\AppData\Local\Programs\Python\Python38\lib\site-packages\flask\app.py", line 1936, in dispatch_request
    return self.view_functions[rule.endpoint](**req.view_args)
  File "app.py", line 60, in index
    latestvenues=db.session.query(Venue).order_by(desc(Venue.id)).limit(10).all(),
  File "C:\Users\Amna\AppData\Local\Programs\Python\Python38\lib\site-packages\sqlalchemy\orm\scoping.py", line 163, in do
    return getattr(self.registry(), name)(*args, **kwargs)
  File "C:\Users\Amna\AppData\Local\Programs\Python\Python38\lib\site-packages\sqlalchemy\util\_collections.py", line 1022, in __call__
    return self.registry.setdefault(key, self.createfunc())
  File "C:\Users\Amna\AppData\Local\Programs\Python\Python38\lib\site-packages\sqlalchemy\orm\session.py", line 3300, in __call__
    return self.class_(**local_kw)
  File "C:\Users\Amna\AppData\Local\Programs\Python\Python38\lib\site-packages\flask_sqlalchemy\__init__.py", line 137, in __init__
    track_modifications = app.config['SQLALCHEMY_TRACK_MODIFICATIONS']
KeyError: 'SQLALCHEMY_TRACK_MODIFICATIONS'
2020-10-28 13:48:08,755 INFO: errors [in C:\Users\Amna\class-demos\fyyur\starter_code\app.py:393]
2020-10-28 13:49:14,227 INFO: errors [in C:\Users\Amna\class-demos\fyyur\starter_code\app.py:393]
2020-10-28 13:49:14,251 INFO: errors [in app.py:393]
2020-10-28 13:49:14,251 INFO: errors [in app.py:393]
2020-10-28 14:17:25,190 INFO: errors [in C:\Users\Amna\class-demos\fyyur\starter_code\app.py:395]
